Workbook

Sheet Dados1
A1: Data | B1: CAMBIOREAL | C1: CDS_5_ANOS | D1: PASSEXTERNO | E1: TOTL | F1: VIXFINAL | G1: DIVBRUTA | H1: SWAPREAL | I1: CRB | J1: IBCBR | K1: USPROD | L1: RESERVAS | M1: IBOV | N1: SeP | P1: LCAMBIOREAL | Q1: LCDS_5_ANOS | R1: LPASSEXTERNO | S1: LTOTL | T1: LVIXFINAL | U1: LDIVBRUTA | V1: LSWAPREAL | W1: LCRB | X1: LIBCBR | Y1: LUSPROD | Z1: LRESERVAS | AA1: LIBOV | AB1: LSeP | AC1: D0804 | AD1: D1503 | AE1: D2002 | AF1: D1301 | AG1: D2018 | AH1: D2024
A2: 2002Q1 | B2: 109.84667 | C2: 793.73 | D2: 0.505 | E2: 87.22 | F2: 20.03 | G2: 0.67836667 | H2: 0.15 | I2: 212.73333 | J2: NA | K2: NA | L2: 372.1 | M2: 13255 | N2: 1147.39 | P2: =LN(B2) -> 4.6990855 | Q2: =LN(C2) -> 6.6767434 | R2: =LN(D2) -> -0.68319685 | S2: =LN(E2) -> 4.4684337 | T2: =LN(F2) -> 2.9972311 | U2: =LN(G2) -> -0.38806733 | V2: =LN(H2) -> -1.89712 | W2: =LN(I2) -> 5.3600394 | ... AB2: =LN(N2) -> 7.0452451 | AC2: 0 | AD2: 0 | AE2: 0 | AF2: 0 | AG2: 0 | AH2: 0
A3: 2002Q2 | B3: 114.32667 | C3: 1132.253 | D3: 0.473 | E3: 88.333333 | F3: 22.43 | G3: 0.70046667 | H3: 0.17065959 | I3: 218.17667 | J3: NA | K3: NA | L3: 320.1 | M3: 11139 | N3: 989.82001 | P3: =LN(B3) -> 4.7390598 | Q3: =LN(C3) -> 7.0319647 | R3: =LN(D3) -> -0.74865989 | S3: =LN(E3) -> 4.4811175 | T3: =LN(F3) -> 3.1103993 | U3: =LN(G3) -> -0.3560085 | V3: =LN(H3) -> -1.7680844 | W3: =LN(I3) -> 5.3853051 | ... AB3: =LN(N3) -> 6.8975231 | AC3: 0 | AD3: 0 | AE3: 0 | AF3: 0 | AG3: 0 | AH3: 0
A4: 2002Q3 | B4: 143.84667 | C4: 2847.31 | D4: 0.408 | E4: 84.82 | F4: 34.79 | G4: 0.77713333 | H4: 0.16565853 | I4: 233.42333 | J4: NA | K4: NA | L4: 484.3 | M4: 8623 | N4: 815.28003 | P4: =LN(B4) -> 4.9687479 | Q4: =LN(C4) -> 7.95413 | R4: =LN(D4) -> -0.8964881 | S4: =LN(E4) -> 4.4405314 | T4: =LN(F4) -> 3.54933 | U4: =LN(G4) -> -0.25214334 | V4: =LN(H4) -> -1.7978267 | W4: =LN(I4) -> 5.4528537 | ... AB4: =LN(N4) -> 6.7035316 | AC4: 0 | AD4: 0 | AE4: 0 | AF4: 0 | AG4: 0 | AH4: 0
A5: 2002Q4 | B5: 162.66333 | C5: 2957.64 | D5: 0.454 | E5: 82.856667 | F5: 29.09 | G5: 0.7696 | H5: 0.14837254 | I5: 238.3 | J5: NA | K5: NA | L5: 432.6 | M5: 11268 | N5: 879.82001 | P5: =LN(B5) -> 5.0916826 | Q5: =LN(C5) -> 7.9921469 | R5: =LN(D5) -> -0.78965808 | S5: =LN(E5) -> 4.4171122 | T5: =LN(F5) -> 3.3703945 | U5: =LN(G5) -> -0.26188438 | V5: =LN(H5) -> -1.908029 | W5: =LN(I5) -> 5.4735304 | ... AB5: =LN(N5) -> 6.7797173 | AC5: 0 | AD5: 0 | AE5: 0 | AF5: 0 | AG5: 0 | AH5: 0
A6: 2003Q1 | B6: 154.13333 | C6: 1684.353 | D6: 0.454 | E6: 83.03 | F6: 29.98 | G6: 0.7714 | H6: 0.13795283 | I6: 248.19333 | J6: 101.82 | K6: NA | L6: 535.4 | M6: 11274 | N6: 848.17999 | P6: =LN(B6) -> 5.037818 | Q6: =LN(C6) -> 7.4291368 | R6: =LN(D6) -> -0.78965808 | S6: =LN(E6) -> 4.419202 | T6: =LN(F6) -> 3.4005305 | U6: =LN(G6) -> -0.25954823 | V6: =LN(H6) -> -1.9808434 | W6: =LN(I6) -> 5.514208 | ... AB6: =LN(N6) -> 6.7430929 | AC6: 0 | AD6: 0 | AE6: 0 | AF6: 0 | AG6: 0 | AH6: 0
A7: 2003Q2 | B7: 133.81667 | C7: 977.6433 | D7: 0.482 | E7: 84.776667 | F7: 20.07 | G7: 0.73133333 | H7: 0.13173367 | I7: 248.70333 | J7: 100.14 | K7: NA | L7: 395.2 | M7: 12973 | N7: 974.5 | P7: =LN(B7) -> 4.8964707 | Q7: =LN(C7) -> 6.8851449 | R7: =LN(D7) -> -0.72981116 | S7: =LN(E7) -> 4.4400203 | T7: =LN(F7) -> 2.9992262 | U7: =LN(G7) -> -0.31288593 | V7: =LN(H7) -> -2.026973 | W7: =LN(I7) -> 5.5162608 | ... AB7: =LN(N7) -> 6.8819245 | AC7: 0 | AD7: 0 | AE7: 0 | AF7: 0 | AG7: 0 | AH7: 0
A8: 2003Q3 | B8: 130.55333 | C8: 818.1333 | D8: 0.475 | E8: 85.19 | F8: 20.28 | G8: 0.74376667 | H8: 0.11732869 | I8: 251.46 | J8: 101.65 | K8: NA | L8: 295.8 | M8: 16011 | N8: 995.96997 | P8: =LN(B8) -> 4.8717818 | Q8: =LN(C8) -> 6.7070253 | R8: =LN(D8) -> -0.74444047 | S8: =LN(E8) -> 4.4448841 | T8: =LN(F8) -> 3.0096352 | U8: =LN(G8) -> -0.29602791 | V8: =LN(H8) -> -2.142776 | W8: =LN(I8) -> 5.5272839 | ... AB8: =LN(N8) -> 6.9037171 | AC8: 0 | AD8: 0 | AE8: 0 | AF8: 0 | AG8: 0 | AH8: 0
A9: 2003Q4 | B9: 130.95333 | C9: 551.6167 | D9: 0.487 | E9: 86 | F9: 16.91 | G9: 0.7274 | H9: 0.091845392 | I9: 274.6 | J9: 101.95 | K9: NA | L9: 305.9 | M9: 22236 | N9: 1111.92 | P9: =LN(B9) -> 4.874841 | Q9: =LN(C9) -> 6.3128534 | R9: =LN(D9) -> -0.71949116 | S9: =LN(E9) -> 4.4543473 | T9: =LN(F9) -> 2.8279052 | U9: =LN(G9) -> -0.31827875 | V9: =LN(H9) -> -2.3876486 | W9: =LN(I9) -> 5.6153155 | ... AB9: =LN(N9) -> 7.0138436 | AC9: 0 | AD9: 0 | AE9: 0 | AF9: 0 | AG9: 0 | AH9: 0
A10: 2004Q1 | B10: 134.72333 | C10: 515.2567 | D10: 0.464 | E10: 86.24 | F10: 15.97 | G10: 0.71863333 | H10: 0.088482707 | I10: 292.08333 | J10: 105.81 | K10: NA | L10: 302.8 | M10: 22142 | N10: 1126.21 | P10: =LN(B10) -> 4.9032233 | Q10: =LN(C10) -> 6.2446652 | R10: =LN(D10) -> -0.76787073 | S10: =LN(E10) -> 4.4571341 | T10: =LN(F10) -> 2.770712 | U10: =LN(G10) -> -0.33040402 | V10: =LN(H10) -> -2.4249481 | W10: =LN(I10) -> 5.6770391 | ... AB10: =LN(N10) -> 7.0266133 | AC10: 0 | AD10: 0 | AE10: 0 | AF10: 0 | AG10: 0 | AH10: 0
A11: 2004Q2 | B11: 140.59 | C11: 734.42 | D11: 0.409 | E11: 87.273333 | F11: 15.68 | G11: 0.70873333 | H11: 0.098123826 | I11: 303.36 | J11: 107.18 | K11: NA | L11: 245.1 | M11: 21149 | N11: 1140.84 | P11: =LN(B11) -> 4.9458479 | Q11: =LN(C11) -> 6.5990811 | R11: =LN(D11) -> -0.89404012 | S11: =LN(E11) -> 4.469045 | T11: =LN(F11) -> 2.752386 | U11: =LN(G11) -> -0.34427594 | V11: =LN(H11) -> -2.3215251 | W11: =LN(I11) -> 5.7149202 | ... AB11: =LN(N11) -> 7.0395201 | AC11: 0 | AD11: 0 | AE11: 0 | AF11: 0 | AG11: 0 | AH11: 0
A12: 2004Q3 | B12: 135.87667 | C12: 551.1367 | D12: 0.42 | E12: 86.613333 | F12: 14.65 | G12: 0.69026667 | H12: 0.097548833 | I12: 292.87667 | J12: 109.16 | K12: NA | L12: 313.1 | M12: 23245 | N12: 1114.58 | P12: =LN(B12) -> 4.9117476 | Q12: =LN(C12) -> 6.3119829 | R12: =LN(D12) -> -0.86750057 | S12: =LN(E12) -> 4.4614538 | T12: =LN(F12) -> 2.6844403 | U12: =LN(G12) -> -0.37067728 | V12: =LN(H12) -> -2.3274022 | W12: =LN(I12) -> 5.6797516 | ... AB12: =LN(N12) -> 7.0162329 | AC12: 0 | AD12: 0 | AE12: 0 | AF12: 0 | AG12: 0 | AH12: 0
A13: 2004Q4 | B13: 128.97 | C13: 381.8267 | D13: 0.444 | E13: 84.673333 | F13: 14.27 | G13: 0.68106667 | H13: 0.10605382 | I13: 296.06667 | J13: 109.07 | K13: NA | L13: 273 | M13: 26196 | N13: 1211.92 | P13: =LN(B13) -> 4.8595798 | Q13: =LN(C13) -> 5.9449668 | R13: =LN(D13) -> -0.81193072 | S13: =LN(E13) -> 4.4388007 | T13: =LN(F13) -> 2.6581594 | U13: =LN(G13) -> -0.38409508 | V13: =LN(H13) -> -2.2438086 | W13: =LN(I13) -> 5.6905847 | ... AB13: =LN(N13) -> 7.0999612 | AC13: 0 | AD13: 0 | AE13: 0 | AF13: 0 | AG13: 0 | AH13: 0
A14: 2005Q1 | B14: 123.12333 | C14: 353.2433 | D14: 0.411 | E14: 85.92 | F14: 12.97 | G14: 0.6815 | H14: 0.11174938 | I14: 292.89 | J14: 110.4 | K14: 13.1 | L14: 293.5 | M14: 26611 | N14: 1180.59 | P14: =LN(B14) -> 4.8131866 | Q14: =LN(C14) -> 5.8671571 | R14: =LN(D14) -> -0.88916206 | S14: =LN(E14) -> 4.4534166 | T14: =LN(F14) -> 2.562639 | U14: =LN(G14) -> -0.38345903 | V14: =LN(H14) -> -2.1914966 | W14: =LN(I14) -> 5.6797971 | ... AB14: =LN(N14) -> 7.0737696 | AC14: 0 | AD14: 0 | AE14: 0 | AF14: 0 | AG14: 0 | AH14: 0
A15: 2005Q2 | B15: 112.75 | C15: 376.2333 | D15: 0.401 | E15: 86.736667 | F15: 13.55 | G15: 0.676 | H15: 0.1134382 | I15: 298.88 | J15: 110.32 | K15: 12.9 | L15: 331.3 | M15: 25051 | N15: 1191.33 | P15: =LN(B15) -> 4.725173 | Q15: =LN(C15) -> 5.9302094 | R15: =LN(D15) -> -0.91379385 | S15: =LN(E15) -> 4.4628767 | T15: =LN(F15) -> 2.6063865 | U15: =LN(G15) -> -0.3915622 | V15: =LN(H15) -> -2.1764971 | W15: =LN(I15) -> 5.7000422 | ... AB15: =LN(N15) -> 7.0828256 | AC15: 0 | AD15: 0 | AE15: 0 | AF15: 0 | AG15: 0 | AH15: 0
A16: 2005Q3 | B16: 105.74333 | C16: 319.4733 | D16: 0.422 | E16: 87.19 | F16: 12.03 | G16: 0.67366667 | H16: 0.11581023 | I16: 292.85 | J16: 110.71 | K16: 13 | L16: 320.4 | M16: 31584 | N16: 1228.8101 | P16: =LN(B16) -> 4.6610148 | Q16: =LN(C16) -> 5.7666737 | R16: =LN(D16) -> -0.86274996 | S16: =LN(E16) -> 4.4680896 | T16: =LN(F16) -> 2.4874035 | U16: =LN(G16) -> -0.39501985 | V16: =LN(H16) -> -2.1558024 | W16: =LN(I16) -> 5.6796605 | ... AB16: =LN(N16) -> 7.1138015 | AC16: 0 | AD16: 0 | AE16: 0 | AF16: 0 | AG16: 0 | AH16: 0
A17: 2005Q4 | B17: 99.663333 | C17: 263.49 | D17: 0.355 | E17: 87.603333 | F17: 13.15 | G17: 0.6712 | H17: 0.11243995 | I17: 295.58 | J17: 112.93 | K17: 13 | L17: 297.4 | M17: 33456 | N17: 1248.29 | P17: =LN(B17) -> 4.6017978 | Q17: =LN(C17) -> 5.5740154 | R17: =LN(D17) -> -1.0356375 | S17: =LN(E17) -> 4.472819 | T17: =LN(F17) -> 2.5764218 | U17: =LN(G17) -> -0.39868812 | V17: =LN(H17) -> -2.185336 | W17: =LN(I17) -> 5.6889395 | ... AB17: =LN(N17) -> 7.1295299 | AC17: 0 | AD17: 0 | AE17: 0 | AF17: 0 | AG17: 0 | AH17: 0
A18: 2006Q1 | B18: 97.136667 | C18: 154.9633 | D18: 0.374 | E18: 88.99 | F18: 12.23 | G18: 0.66796667 | H18: 0.10920686 | I18: 308.24 | J18: 113.47 | K18: 13.1 | L18: 489.1 | M18: 37952 | N18: 1294.87 | P18: =LN(B18) -> 4.5761189 | Q18: =LN(C18) -> 5.0431883 | R18: =LN(D18) -> -0.98349948 | S18: =LN(E18) -> 4.488524 | T18: =LN(F18) -> 2.5038919 | U18: =LN(G18) -> -0.40351701 | V18: =LN(H18) -> -2.2145114 | W18: =LN(I18) -> 5.7308787 | ... AB18: =LN(N18) -> 7.1661656 | AC18: 0 | AD18: 0 | AE18: 0 | AF18: 0 | AG18: 0 | AH18: 0
A19: 2006Q2 | B19: 98.933333 | C19: 163.08 | D19: 0.344 | E19: 89.19 | F19: 13.7 | G19: 0.64083333 | H19: 0.10086442 | I19: 324.05667 | J19: 114.34 | K19: 13.1 | L19: 701.9 | M19: 36631 | N19: 1270.2 | P19: =LN(B19) -> 4.5944462 | Q19: =LN(C19) -> 5.0942409 | R19: =LN(D19) -> -1.0671136 | S19: =LN(E19) -> 4.4907689 | T19: =LN(F19) -> 2.6173958 | U19: =LN(G19) -> -0.44498587 | V19: =LN(H19) -> -2.293978 | W19: =LN(I19) -> 5.7809184 | ... AB19: =LN(N19) -> 7.1469296 | AC19: 0 | AD19: 0 | AE19: 0 | AF19: 0 | AG19: 0 | AH19: 0
A20: 2006Q3 | B20: 99.486667 | C20: 137.6567 | D20: 0.32 | E20: 93.133333 | F20: 13.08 | G20: 0.6385 | H20: 0.086304603 | I20: 339.31 | J20: 116.69 | K20: 12.9 | L20: 735.1 | M20: 36449 | N20: 1335.85 | P20: =LN(B20) -> 4.6000236 | Q20: =LN(C20) -> 4.9247629 | R20: =LN(D20) -> -1.1394343 | S20: =LN(E20) -> 4.5340322 | T20: =LN(F20) -> 2.5710843 | U20: =LN(G20) -> -0.4486336 | V20: =LN(H20) -> -2.4498723 | W20: =LN(I20) -> 5.8269141 | ... AB20: =LN(N20) -> 7.1973231 | AC20: 0 | AD20: 0 | AE20: 0 | AF20: 0 | AG20: 0 | AH20: 0
A21: 2006Q4 | B21: 98.543333 | C21: 109.94 | D21: 0.335 | E21: 94.7 | F21: 11.19 | G21: 0.644 | H21: 0.081273541 | I21: 351.90333 | J21: 120.72 | K21: 12.9 | L21: 900.4 | M21: 44474 | N21: 1418.3 | P21: =LN(B21) -> 4.5904964 | Q21: =LN(C21) -> 4.6999348 | R21: =LN(D21) -> -1.0936247 | S21: =LN(E21) -> 4.550714 | T21: =LN(F21) -> 2.4150205 | U21: =LN(G21) -> -0.44005655 | V21: =LN(H21) -> -2.5099348 | W21: =LN(I21) -> 5.8633565 | ... AB21: =LN(N21) -> 7.2572143 | AC21: 0 | AD21: 0 | AE21: 0 | AF21: 0 | AG21: 0 | AH21: 0
A22: 2007Q1 | B22: 96.613333 | C22: 93.38333 | D22: 0.325 | E22: 95.526667 | F22: 13.49 | G22: 0.6427 | H22: 0.076400284 | I22: 365.15667 | J22: 119.48 | K22: 12.7 | L22: 1085.7 | M22: 45805 | N22: 1420.86 | P22: =LN(B22) -> 4.5707168 | Q22: =LN(C22) -> 4.5367128 | R22: =LN(D22) -> -1.1239301 | S22: =LN(E22) -> 4.5594054 | T22: =LN(F22) -> 2.6019487 | U22: =LN(G22) -> -0.44207723 | V22: =LN(H22) -> -2.5717689 | W22: =LN(I22) -> 5.9003265 | ... AB22: =LN(N22) -> 7.2590176 | AC22: 0 | AD22: 0 | AE22: 0 | AF22: 0 | AG22: 0 | AH22: 0
A23: 2007Q2 | B23: 92.403333 | C23: 69.6 | D23: 0.354 | E23: 93.483333 | F23: 14.5 | G23: 0.63976667 | H23: 0.074138356 | I23: 392.82667 | J23: 123 | K23: 12.9 | L23: 1473.4 | M23: 54392 | N23: 1503.35 | P23: =LN(B23) -> 4.5261631 | Q23: =LN(C23) -> 4.2427646 | R23: =LN(D23) -> -1.0384584 | S23: =LN(E23) -> 4.5377832 | T23: =LN(F23) -> 2.6741486 | U23: =LN(G23) -> -0.44665175 | V23: =LN(H23) -> -2.6018223 | W23: =LN(I23) -> 5.9733685 | ... AB23: =LN(N23) -> 7.3154512 | AC23: 0 | AD23: 0 | AE23: 0 | AF23: 0 | AG23: 0 | AH23: 0
A24: 2007Q3 | B24: 90.336667 | C24: 99.87333 | D24: 0.389 | E24: 94.16 | F24: 21.63 | G24: 0.62426667 | H24: 0.069447278 | I24: 407.35667 | J24: 125.1 | K24: 12.8 | L24: 1862.9 | M24: 60465 | N24: 1526.75 | P24: =LN(B24) -> 4.5035434 | Q24: =LN(C24) -> 4.6039027 | R24: =LN(D24) -> -0.94417594 | S24: =LN(E24) -> 4.5449955 | T24: =LN(F24) -> 3.0740812 | U24: =LN(G24) -> -0.47117765 | V24: =LN(H24) -> -2.6671874 | W24: =LN(I24) -> 6.0096891 | ... AB24: =LN(N24) -> 7.3308966 | AC24: 0 | AD24: 0 | AE24: 0 | AF24: 0 | AG24: 0 | AH24: 0
A25: 2007Q4 | B25: 86.34 | C25: 95.59667 | D25: 0.392 | E25: 96.143333 | F25: 21.3 | G25: 0.6297 | H25: 0.069586475 | I25: 415.88333 | J25: 127.62 | K25: 12.7 | L25: 1918.2 | M25: 63886 | N25: 1468.36 | P25: =LN(B25) -> 4.458293 | Q25: =LN(C25) -> 4.560138 | R25: =LN(D25) -> -0.93649344 | S25: =LN(E25) -> 4.5658401 | T25: =LN(F25) -> 3.0587071 | U25: =LN(G25) -> -0.46251176 | V25: =LN(H25) -> -2.6651851 | W25: =LN(I25) -> 6.0304048 | ... AB25: =LN(N25) -> 7.2919014 | AC25: 0 | AD25: 0 | AE25: 0 | AF25: 0 | AG25: 0 | AH25: 0
... A74: 2020Q1 | B74: 120.77 | C74: 166 | D74: 0.239 | E74: 100.26667 | F74: 27 | G74: 0.8635 | H74: 0.0056 | I74: 381.33333 | J74: 129.88 | K74: 10.2 | L74: 1702.2 | M74: 73020 | N74: 2584.5901 | P74: =LN(B74) -> 4.7938879 | Q74: =LN(C74) -> 5.1119878 | R74: =LN(D74) -> -1.4312917 | S74: =LN(E74) -> 4.6078333 | T74: =LN(F74) -> 3.2958369 | U74: =LN(G74) -> -0.14676138 | V74: =LN(H74) -> -5.1849887 | W74: =LN(I74) -> 5.9436739 | ... AB74: =LN(N74) -> 7.8573222 | AC74: 0 | AD74: 0 | AE74: 0 | AF74: 0 | AG74: 0 | AH74: 0
A75: 2020Q2 | B75: 143.49 | C75: 300 | D75: 0.261 | E75: 96.653333 | F75: 20 | G75: 0.8819 | H75: -0.003875969 | I75: 359.33333 | J75: 126.91 | K75: 9.9 | L75: 1439.3 | M75: 95056 | N75: 3100.29 | P75: =LN(B75) -> 4.9662653 | Q75: =LN(C75) -> 5.7037825 | R75: =LN(D75) -> -1.3432349 | S75: =LN(E75) -> 4.5711307 | T75: =LN(F75) -> 2.9957323 | U75: =LN(G75) -> -0.12567661 | V75: =LN(1+H75) -> -0.0038835 | W75: =LN(I75) -> 5.8842505 | X75: =LN(J75) -> 4.8434782 | Y75: =LN(K75) -> 2.2925348 | Z75: =LN(L75) -> 7.2719122 | AA75: =LN(M75) -> 11.462221 | AB75: =LN(N75) -> 8.0392509 | AC75: 0 | AD75: 0 | AE75: 0 | AF75: 0 | AG75: 0 | AH75: 0
A76: 2020Q3 | B76: 148.15 | C76: 200 | D76: 0.26 | E76: 98.716667 | F76: 18 | G76: 0.89433333 | H76: -0.004365939 | I76: 393.33333 | J76: 136.54 | K76: 10.1 | L76: 1240.3 | M76: 94603 | N76: 3363 | P76: =LN(B76) -> 4.9982253 | Q76: =LN(C76) -> 5.2983174 | R76: =LN(D76) -> -1.3470736 | S76: =LN(E76) -> 4.5922538 | T76: =LN(F76) -> 2.8903718 | U76: =LN(G76) -> -0.11167672 | V76: =LN(1+H76) -> -0.0043754975 | W76: =LN(I76) -> 5.9746574 | X76: =LN(J76) -> 4.9166176 | Y76: =LN(K76) -> 2.3125354 | Z76: =LN(L76) -> 7.1231086 | AA76: =LN(M76) -> 11.457444 | AB76: =LN(N76) -> 8.1205887 | AC76: 0 | AD76: 0 | AE76: 0 | AF76: 0 | AG76: 0 | AH76: 0
A77: 2020q4 | B77: 147.9 | C77: 174 | D77: 0.383 | E77: 107.56333 | F77: 27 | G77: 0.9408 | H77: -0.001572955 | I77: 443 | J77: 139.55 | K77: 10.1 | L77: 1234.4 | M77: 119306 | N77: 3756.0701 | P77: =LN(B77) -> 4.9965364 | Q77: =LN(C77) -> 5.1590553 | R77: =LN(D77) -> -0.95972029 | S77: =LN(E77) -> 4.6780798 | T77: =LN(F77) -> 3.2958369 | U77: =LN(G77) -> -0.061024702 | V77: =LN(1+H77) -> -0.0015741934 | W77: =LN(I77) -> 6.0935698 | X77: =LN(J77) -> 4.938423 | Y77: =LN(K77) -> 2.3125354 | Z77: =LN(L77) -> 7.1183403 | AA77: =LN(M77) -> 11.689447 | AB77: =LN(N77) -> 8.2311285 | AC77: 0 | AD77: 0 | AE77: 0 | AF77: 0 | AG77: 0 | AH77: 0
A78: 2021q1 | B78: 149.35 | C78: 194 | D78: 0.315 | E78: 116.8 | F78: 25 | G78: 0.96106667 | H78: 0.0017 | I78: 506 | J78: 136.17 | K78: 10.1 | L78: 1130.8 | M78: 116634 | N78: 3972.8899 | P78: =LN(B78) -> 5.0062925 | Q78: =LN(C78) -> 5.2678582 | R78: =LN(D78) -> -1.1551826 | S78: =LN(E78) -> 4.7604631 | T78: =LN(F78) -> 3.2188758 | U78: =LN(G78) -> -0.0397115 | V78: =LN(H78) -> -6.377127 | W78: =LN(I78) -> 6.2265367 | ... AB78: =LN(N78) -> 8.287249 | AC78: 0 | AD78: 0 | AE78: 0 | AF78: 0 | AG78: 0 | AH78: 0
A79: 2021q2 | B79: 143.97 | C79: 174 | D79: 0.399 | E79: 116.54667 | F79: 16.6 | G79: 0.9174 | H79: 0.0193 | I79: 562 | J79: 138.9 | K79: 10.1 | L79: 1206 | M79: 126802 | N79: 4297.5 | P79: =LN(B79) -> 4.9696049 | Q79: =LN(C79) -> 5.1590553 | R79: =LN(D79) -> -0.91879386 | S79: =LN(E79) -> 4.7582918 | T79: =LN(F79) -> 2.8094027 | U79: =LN(G79) -> -0.086211697 | V79: =LN(H79) -> -3.9476502 | W79: =LN(I79) -> 6.3315018 | ... AB79: =LN(N79) -> 8.3657887 | AC79: 0 | AD79: 0 | AE79: 0 | AF79: 0 | AG79: 0 | AH79: 0
A80: 2021q3 | B80: 140 | C80: 183 | D80: 0.304 | E80: 117 | F80: 19 | G80: 0.9037 | H80: 0.036 | I80: 571 | J80: 138.53 | K80: 10.1 | L80: 1371.5 | M80: 110979 | N80: 4307.54 | P80: =LN(B80) -> 4.9416424 | Q80: =LN(C80) -> 5.2094862 | R80: =LN(D80) -> -1.1907276 | S80: =LN(E80) -> 4.7621739 | T80: =LN(F80) -> 2.944439 | U80: =LN(G80) -> -0.10125783 | V80: =LN(H80) -> -3.3242363 | W80: =LN(I80) -> 6.3473892 | ... AB80: =LN(N80) -> 8.3681223 | AC80: 0 | AD80: 0 | AE80: 0 | AF80: 0 | AG80: 0 | AH80: 0
A81: 2021q4 | B81: 144.6 | C81: 233 | D81: 0.367 | E81: 106 | F81: 17.3 | G81: 0.8836 | H81: 0.0628 | I81: 578 | J81: 141.36 | K81: 10.3 | L81: 1297 | M81: 104822 | N81: 4766.1802 | P81: =LN(B81) -> 4.9739713 | Q81: =LN(C81) -> 5.4510385 | R81: =LN(D81) -> -1.0023934 | S81: =LN(E81) -> 4.6634391 | T81: =LN(F81) -> 2.8507065 | U81: =LN(G81) -> -0.12375081 | V81: =LN(H81) -> -2.7678002 | W81: =LN(I81) -> 6.3595739 | ... AB81: =LN(N81) -> 8.4693005 | AC81: 0 | AD81: 0 | AE81: 0 | AF81: 0 | AG81: 0 | AH81: 0
A82: 2022q1 | B82: 134.6 | C82: 216 | D82: 0.512 | E82: 106.81 | F82: 24.6 | G82: 0.88 | H82: 0.077 | I82: 634 | J82: 142.33 | K82: 10.3 | L82: 1318.9 | M82: 119999 | N82: 4530.4102 | P82: =LN(B82) -> 4.9023074 | Q82: =LN(C82) -> 5.3752784 | R82: =LN(D82) -> -0.66943065 | S82: =LN(E82) -> 4.6710516 | T82: =LN(F82) -> 3.2027464 | U82: =LN(G82) -> -0.12783337 | V82: =LN(H82) -> -2.5639499 | W82: =LN(I82) -> 6.452049 | ... AB82: =LN(N82) -> 8.4185678 | AC82: 0 | AD82: 0 | AE82: 1 | AF82: 0 | AG82: 0 | AH82: 0
A83: 2022q2 | B83: 121.94 | C83: 250 | D83: 0.401 | E83: 105.3 | F83: 28.1 | G83: 0.869 | H83: 0.077 | I83: 596 | J83: 143.35 | K83: 10.4 | L83: 1462.2 | M83: 98542 | N83: 3785.3799 | P83: =LN(B83) -> 4.8035291 | Q83: =LN(C83) -> 5.5214609 | R83: =LN(D83) -> -0.91379385 | S83: =LN(E83) -> 4.6568134 | T83: =LN(F83) -> 3.3357696 | U83: =LN(G83) -> -0.14041215 | V83: =LN(H83) -> -2.5639499 | W83: =LN(I83) -> 6.3902407 | ... AB83: =LN(N83) -> 8.2389015 | AC83: 0 | AD83: 0 | AE83: 0 | AF83: 0 | AG83: 0 | AH83: 0
A84: 2022q3 | B84: 129.8 | C84: 273 | D84: 0.395 | E84: 108.15 | F84: 22.2 | G84: 0.8463 | H84: 0.077 | I84: 559 | J84: 144.01 | K84: 10.2 | L84: 1678.3 | M84: 110037 | N84: 3585.6201 | P84: =LN(B84) -> 4.8659948 | Q84: =LN(C84) -> 5.6094718 | R84: =LN(D84) -> -0.92886951 | S84: =LN(E84) -> 4.6835192 | T84: =LN(F84) -> 3.1000923 | U84: =LN(G84) -> -0.16688137 | V84: =LN(H84) -> -2.5639499 | W84: =LN(I84) -> 6.3261495 | ... AB84: =LN(N84) -> 8.1846867 | AC84: 0 | AD84: 0 | AE84: 0 | AF84: 0 | AG84: 0 | AH84: 0
A85: 2022q4 | B85: 128 | C85: 259 | D85: 0.422 | E85: 106 | F85: 20.6 | G85: 0.8344 | H85: 0.0769 | I85: 554 | J85: 142.93 | K85: 10.4 | L85: 1724.8 | M85: 110031 | N85: 3839.5 | P85: =LN(B85) -> 4.8520303 | Q85: =LN(C85) -> 5.5568281 | R85: =LN(D85) -> -0.86274996 | S85: =LN(E85) -> 4.6634391 | T85: =LN(F85) -> 3.0252911 | U85: =LN(G85) -> -0.18104238 | V85: =LN(H85) -> -2.5652494 | W85: =LN(I85) -> 6.3171647 | ... AB85: =LN(N85) -> 8.2530974 | AC85: 0 | AD85: 0 | AE85: 0 | AF85: 0 | AG85: 0 | AH85: 0
A86: 2023q1 | B86: 129 | C86: 225 | D86: 0.419 | E86: 105.8 | F86: 20.23 | G86: 0.816 | H86: 0.0713 | I86: 550 | J86: 147.5 | K86: 10.2 | L86: 1708.4 | M86: 101882 | N86: 4109.3101 | P86: =LN(B86) -> 4.8598124 | Q86: =LN(C86) -> 5.4161004 | R86: =LN(D86) -> -0.86988436 | S86: =LN(E86) -> 4.6615505 | T86: =LN(F86) -> 3.0071667 | U86: =LN(G86) -> -0.20334092 | V86: =LN(H86) -> -2.640859 | W86: =LN(I86) -> 6.3099183 | ... AB86: =LN(N86) -> 8.3210104 | AC86: 0 | AD86: 0 | AE86: 0 | AF86: 0 | AG86: 0 | AH86: 0
A87: 2023q2 | B87: 120.88 | C87: 200 | D87: 0.461 | E87: 108 | F87: 16.6 | G87: 0.8272 | H87: 0.07 | I87: 547 | J87: =J86+1.57 -> 149.07 | K87: 10.2 | L87: 1866.4 | M87: 118087 | N87: 4450.3799 | P87: =LN(B87) -> 4.7947983 | Q87: =LN(C87) -> 5.2983174 | R87: =LN(D87) -> -0.77435724 | S87: =LN(E87) -> 4.6821312 | T87: =LN(F87) -> 2.8094027 | U87: =LN(G87) -> -0.18970878 | V87: =LN(H87) -> -2.65926 | W87: =LN(I87) -> 6.3044488 | ... AB87: =LN(N87) -> 8.4007447 | AC87: 0 | AD87: 0 | AE87: 0 | AF87: 0 | AG87: 0 | AH87: 0
A88: 2023q3 | B88: 118.77 | C88: 171 | D88: 0.431 | E88: 110.3 | F88: 15.8 | G88: 0.8252 | H88: 0.066 | I88: 555 | J88: =J87+1.57 -> 150.64 | K88: 10.3 | L88: 1839.9 | M88: 116565 | N88: 4288.0498 | P88: =LN(B88) -> 4.7771888 | Q88: =LN(C88) -> 5.1416636 | R88: =LN(D88) -> -0.84164719 | S88: =LN(E88) -> 4.7032039 | T88: =LN(F88) -> 2.7600099 | U88: =LN(G88) -> -0.1921295 | V88: =LN(H88) -> -2.7181005 | W88: =LN(I88) -> 6.3189681 | ... AB88: =LN(N88) -> 8.3635873 | AC88: 0 | AD88: 0 | AE88: 0 | AF88: 0 | AG88: 0 | AH88: 0
...

Sheet IBOV
A1: Data | B1: LCAMBIOREAL | C1: LCDS_5_ANOS | D1: LPASSEXTERNO | E1: LTOTL | F1: LVIXFINAL | G1: LDIVBRUTA | H1: LSWAPREAL | I1: LCRB | J1: LIBCBR | K1: LUSPROD | L1: LRESERVAS | M1: LIBOV | N1: LSeP | O1: D0804 | P1: D1503 | Q1: D2002 | R1: D1301 | S1: D2018 | T1: D2024
A2: 2005Q1 | B2: 4.8131866 | C2: 5.8671571 | D2: -0.88916206 | E2: 4.4534166 | F2: 2.562639 | G2: -0.38345903 | H2: -2.1914966 | I2: 5.6797971 | J2: 4.7041101 | K2: 2.5726122 | L2: 5.6818776 | M2: 10.18908 | N2: 7.0737696 | O2: 0 | P2: 0 | Q2: 0 | R2: 0 | S2: 0 | T2: 0
A3: 2005Q2 | B3: 4.725173 | C3: 5.9302094 | D3: -0.91379385 | E3: 4.4628767 | F3: 2.6063865 | G3: -0.3915622 | H3: -2.1764971 | I3: 5.7000422 | J3: 4.7033852 | K3: 2.5572273 | L3: 5.8030243 | M3: 10.128669 | N3: 7.0828256 | O3: 0 | P3: 0 | Q3: 0 | R3: 0 | S3: 0 | T3: 0
A4: 2005Q3 | B4: 4.6610148 | C4: 5.7666737 | D4: -0.86274996 | E4: 4.4680896 | F4: 2.4874035 | G4: -0.39501985 | H4: -2.1558024 | I4: 5.6796605 | J4: 4.7069142 | K4: 2.5649494 | L4: 5.7695702 | M4: 10.360406 | N4: 7.1138015 | O4: 0 | P4: 0 | Q4: 0 | R4: 0 | S4: 0 | T4: 0
A5: 2005Q4 | B5: 4.6017978 | C5: 5.5740154 | D5: -1.0356375 | E5: 4.472819 | F5: 2.5764218 | G5: -0.39868812 | H5: -2.185336 | I5: 5.6889395 | J5: 4.7267682 | K5: 2.5649494 | L5: 5.695078 | M5: 10.417986 | N5: 7.1295299 | O5: 0 | P5: 0 | Q5: 0 | R5: 0 | S5: 0 | T5: 0
A6: 2006Q1 | B6: 4.5761189 | C6: 5.0431883 | D6: -0.98349948 | E6: 4.488524 | F6: 2.5038919 | G6: -0.40351701 | H6: -2.2145114 | I6: 5.7308787 | J6: 4.7315385 | K6: 2.5726122 | L6: 6.192567 | M6: 10.544077 | N6: 7.1661656 | O6: 0 | P6: 0 | Q6: 0 | R6: 0 | S6: 0 | T6: 0
A7: 2006Q2 | B7: 4.5944462 | C7: 5.0942409 | D7: -1.0671136 | E7: 4.4907689 | F7: 2.6173958 | G7: -0.44498587 | H7: -2.293978 | I7: 5.7809184 | J7: 4.7391765 | K7: 2.5726122 | L7: 6.5537909 | M7: 10.50865 | N7: 7.1469296 | O7: 0 | P7: 0 | Q7: 0 | R7: 0 | S7: 0 | T7: 0
A8: 2006Q3 | B8: 4.6000236 | C8: 4.9247629 | D8: -1.1394343 | E8: 4.5340322 | F8: 2.5710843 | G8: -0.4486336 | H8: -2.4498723 | I8: 5.8269141 | J8: 4.7595208 | K8: 2.5572273 | L8: 6.6000065 | M8: 10.503669 | N8: 7.1973231 | O8: 0 | P8: 0 | Q8: 0 | R8: 0 | S8: 0 | T8: 0
A9: 2006Q4 | B9: 4.5904964 | C9: 4.6999348 | D9: -1.0936247 | E9: 4.550714 | F9: 2.4150205 | G9: -0.44005655 | H9: -2.5099348 | I9: 5.8633565 | J9: 4.7934738 | K9: 2.5572273 | L9: 6.8028391 | M9: 10.70266 | N9: 7.2572143 | O9: 0 | P9: 0 | Q9: 0 | R9: 0 | S9: 0 | T9: 0
A10: 2007Q1 | B10: 4.5707168 | C10: 4.5367128 | D10: -1.1239301 | E10: 4.5594054 | F10: 2.6019487 | G10: -0.44207723 | H10: -2.5717689 | I10: 5.9003265 | J10: 4.783149 | K10: 2.541602 | L10: 6.9899802 | M10: 10.732149 | N10: 7.2590176 | O10: 0 | P10: 0 | Q10: 0 | R10: 0 | S10: 0 | T10: 0
A11: 2007Q2 | B11: 4.5261631 | C11: 4.2427646 | D11: -1.0384584 | E11: 4.5377832 | F11: 2.6741486 | G11: -0.44665175 | H11: -2.6018223 | I11: 5.9733685 | J11: 4.8121844 | K11: 2.5572273 | L11: 7.2953279 | M11: 10.903972 | N11: 7.3154512 | O11: 0 | P11: 0 | Q11: 0 | R11: 0 | S11: 0 | T11: 0
A12: 2007Q3 | B12: 4.5035434 | C12: 4.6039027 | D12: -0.94417594 | E12: 4.5449955 | F12: 3.0740812 | G12: -0.47117765 | H12: -2.6671874 | I12: 6.0096891 | J12: 4.8291134 | K12: 2.5494452 | L12: 7.5298897 | M12: 11.00982 | N12: 7.3308966 | O12: 0 | P12: 0 | Q12: 0 | R12: 0 | S12: 0 | T12: 0
A13: 2007Q4 | B13: 4.458293 | C13: 4.560138 | D13: -0.93649344 | E13: 4.5658401 | F13: 3.0587071 | G13: -0.46251176 | H13: -2.6651851 | I13: 6.0304048 | J13: 4.8490571 | K13: 2.541602 | L13: 7.5591425 | M13: 11.064856 | N13: 7.2919014 | O13: 0 | P13: 0 | Q13: 0 | R13: 0 | S13: 0 | T13: 0
... A81: 2024q4 | B81: 4.9115513 | C81: 5.2832037 | D81: -0.89159812 | E81: 4.7597779 | F81: 2.9724636 | G81: -0.13604884 | H81: -2.512319 | I81: 6.2841342 | J81: 5.0656915 | K81: 2.2925348 | L81: 7.7218361 | M81: 11.697603 | N81: 8.6795892 | O81: 0 | P81: 0 | Q81: 0 | R81: 0 | S81: 0 | T81: 1
A82: 2025q1 | B82: 4.8893712 | C82: 5.288267 | D82: -0.86750057 | E82: 4.7397885 | F82: 3.6259397 | G82: -0.12488318 | H82: -2.4595898 | I82: 6.3044488 | J82: 5.0755487 | K82: 2.2721259 | L82: 7.6349657 | M82: 11.777288 | N82: =8.63263572982787*2.5 -> 21.581589 | O82: 0 | P82: 0 | Q82: 0 | R82: 0 | S82: 0 | T82: 0
A83: 2025q2 | B83: =Modelo!$B$2+Modelo!$B$3*B82+Modelo!$B$4*B81+Modelo!$B$5*C83+Modelo!$B$6*H81+Modelo!$B$7*E84+Modelo!$B$8*D82+Modelo!$B$9*G83+Modelo!$B$12*N83+Modelo!$B$13*M83 -> 4.8451594 | C83: 5.288267 | D83: -0.86750057 | E83: 4.7397885 | F83: 3.6259397 | G83: -0.12488318 | H83: -2.4595898 | I83: 6.3044488 | J83: 5.0755487 | M83: =M82*O84 -> 12.130606 | N83: =N82 -> 21.581589
A84: 2025q3 | B84: =Modelo!$B$2+Modelo!$B$3*B83+Modelo!$B$4*B82+Modelo!$B$5*C84+Modelo!$B$6*H82+Modelo!$B$7*E85+Modelo!$B$8*D83+Modelo!$B$9*G84+Modelo!$B$12*N84+Modelo!$B$13*M84 -> 4.780994 | C84: 5.288267 | D84: -0.86750057 | E84: 4.7397885 | F84: 3.6259397 | G84: -0.12488318 | H84: -2.4595898 | I84: 6.3044488 | J84: 5.0755487 | M84: =M83*O85 -> 12.494525 | N84: =N83 -> 21.581589 | O84: 1.03
A85: 2025q4 | B85: =Modelo!$B$2+Modelo!$B$3*B84+Modelo!$B$4*B83+Modelo!$B$5*C85+Modelo!$B$6*H83+Modelo!$B$7*E86+Modelo!$B$8*D84+Modelo!$B$9*G85+Modelo!$B$12*N85+Modelo!$B$13*M85 -> 4.7301228 | C85: 5.288267 | D85: -0.86750057 | E85: 4.7397885 | F85: 3.6259397 | G85: -0.12488318 | H85: -2.4595898 | I85: 6.3044488 | J85: 5.0755487 | M85: =M84*O86 -> 12.86936 | N85: =N84 -> 21.581589 | O85: 1.03
A86: 2026q1 | B86: =Modelo!$B$2+Modelo!$B$3*B85+Modelo!$B$4*B84+Modelo!$B$5*C86+Modelo!$B$6*H84+Modelo!$B$7*E87+Modelo!$B$8*D85+Modelo!$B$9*G86+Modelo!$B$12*N86+Modelo!$B$13*M86 -> 4.6719794 | C86: 5.288267 | D86: -0.86750057 | E86: 4.7397885 | F86: 3.6259397 | G86: -0.12488318 | H86: -2.4595898 | I86: 6.3044488 | J86: 5.0755487 | M86: =M85*O87 -> 13.255441 | N86: =N85 -> 21.581589 | O86: 1.03
A87: 2026q2 | B87: =Modelo!$B$2+Modelo!$B$3*B86+Modelo!$B$4*B85+Modelo!$B$5*C87+Modelo!$B$6*H85+Modelo!$B$7*E88+Modelo!$B$8*D86+Modelo!$B$9*G87+Modelo!$B$12*N87+Modelo!$B$13*M87 -> 4.616164 | C87: 5.288267 | D87: -0.86750057 | E87: 4.7397885 | F87: 3.6259397 | G87: -0.12488318 | H87: -2.4595898 | I87: 6.3044488 | J87: 5.0755487 | M87: =M86*O88 -> 13.653104 | N87: =N86 -> 21.581589 | O87: 1.03
A88: 2026q3 | B88: =Modelo!$B$2+Modelo!$B$3*B87+Modelo!$B$4*B86+Modelo!$B$5*C88+Modelo!$B$6*H86+Modelo!$B$7*E89+Modelo!$B$8*D87+Modelo!$B$9*G88+Modelo!$B$12*N88+Modelo!$B$13*M88 -> 4.5569596 | C88: 5.288267 | D88: -0.86750057 | E88: 4.7397885 | F88: 3.6259397 | G88: -0.12488318 | H88: -2.4595898 | I88: 6.3044488 | J88: 5.0755487 | M88: =M87*O89 -> 14.062697 | N88: =N87 -> 21.581589 | O88: 1.03
A89: 2026q4 | B89: =Modelo!$B$2+Modelo!$B$3*B88+Modelo!$B$4*B87+Modelo!$B$5*C89+Modelo!$B$6*H87+Modelo!$B$7*E90+Modelo!$B$8*D88+Modelo!$B$9*G89+Modelo!$B$12*N89+Modelo!$B$13*M89 -> 4.4970852 | C89: 5.288267 | D89: -0.86750057 | E89: 4.7397885 | F89: 3.6259397 | G89: -0.12488318 | H89: -2.4595898 | I89: 6.3044488 | J89: 5.0755487 | M89: =M88*O90 -> 14.484578 | N89: =N88 -> 21.581589 | O89: 1.03
A90: 2027q1 | B90: =Modelo!$B$2+Modelo!$B$3*B89+Modelo!$B$4*B88+Modelo!$B$5*C90+Modelo!$B$6*H88+Modelo!$B$7*E91+Modelo!$B$8*D89+Modelo!$B$9*G90+Modelo!$B$12*N90+Modelo!$B$13*M90 -> 4.434913 | C90: 5.288267 | D90: -0.86750057 | E90: 4.7397885 | F90: 3.6259397 | G90: -0.12488318 | H90: -2.4595898 | I90: 6.3044488 | J90: 5.0755487 | M90: =M89*O91 -> 14.919116 | N90: =N89 -> 21.581589 | O90: 1.03
A91: 2027q2 | B91: =Modelo!$B$2+Modelo!$B$3*B90+Modelo!$B$4*B89+Modelo!$B$5*C91+Modelo!$B$6*H89+Modelo!$B$7*E92+Modelo!$B$8*D90+Modelo!$B$9*G91+Modelo!$B$12*N91+Modelo!$B$13*M91 -> 4.3711795 | C91: 5.288267 | D91: -0.86750057 | E91: 4.7397885 | F91: 3.6259397 | G91: -0.12488318 | H91: -2.4595898 | I91: 6.3044488 | J91: 5.0755487 | M91: =M90*O92 -> 15.366689 | N91: =N90 -> 21.581589 | O91: 1.03
A92: 2027q3 | B92: =Modelo!$B$2+Modelo!$B$3*B91+Modelo!$B$4*B90+Modelo!$B$5*C92+Modelo!$B$6*H90+Modelo!$B$7*E93+Modelo!$B$8*D91+Modelo!$B$9*G92+Modelo!$B$12*N92+Modelo!$B$13*M92 -> 4.3053892 | C92: 5.288267 | D92: -0.86750057 | E92: 4.7397885 | F92: 3.6259397 | G92: -0.12488318 | H92: -2.4595898 | I92: 6.3044488 | J92: 5.0755487 | M92: =M91*O93 -> 15.82769 | N92: =N91 -> 21.581589 | O92: 1.03
A93: 2027q4 | B93: =Modelo!$B$2+Modelo!$B$3*B92+Modelo!$B$4*B91+Modelo!$B$5*C93+Modelo!$B$6*H91+Modelo!$B$7*E94+Modelo!$B$8*D92+Modelo!$B$9*G93+Modelo!$B$12*N93+Modelo!$B$13*M93 -> 4.2377092 | C93: 5.288267 | D93: -0.86750057 | E93: 4.7397885 | F93: 3.6259397 | G93: -0.12488318 | H93: -2.4595898 | I93: 6.3044488 | J93: 5.0755487 | M93: =M92*O94 -> 16.302521 | N93: =N92 -> 21.581589 | O93: 1.03
E94: 4.7397885 | O94: 1.03
A95: 2024q2 | B95: 4.8081927 | C95: 4.9767337 | D95: -0.86750057 | E95: 4.7126784 | F95: 2.5063419 | G95: -0.13284591 | H95: -2.7257051 | I95: 6.2897156 | J95: 5.0456806 | K95: 2.3025851 | L95: 7.6979384 | M95: 11.727287 | N95: 8.605292
A96: 2024q3 | B96: 4.8917016 | C96: 5.0434251 | D96: -0.83240925 | E96: 4.7376886 | F96: 3.0184718 | G96: -0.16369609 | H96: -2.6333139 | I96: 6.2915691 | J96: 5.0557361 | K96: 2.3025851 | L96: 7.7214373 | M96: 11.789162 | N96: 8.6591232
A97: 2024q4 | B97: 4.9115513 | C97: 5.2832037 | D97: -0.89159812 | E97: 4.7597779 | F97: 2.9724636 | G97: -0.13604884 | H97: -2.512319 | I97: 6.2841342 | J97: 5.0656915 | K97: 2.2925348 | L97: 7.7218361 | M97: 11.697603 | N97: 8.6795892
A98: 2025q1 | B98: 4.8893712 | C98: 5.288267 | D98: -0.86750057 | E98: 4.7397885 | F98: 3.6259397 | G98: -0.12488318 | H98: -2.4595898 | I98: 6.3044488 | J98: 5.0755487 | K98: 2.2721259 | L98: 7.6349657 | M98: 11.777288 | N98: =8.63263572982787*2.5 -> 21.581589 | O98: 0.97
A99: 2025q2 | B99: =Modelo!$B$2+Modelo!$B$3*B98+Modelo!$B$4*B97+Modelo!$B$5*C99+Modelo!$B$6*H97+Modelo!$B$7*E100+Modelo!$B$8*D98+Modelo!$B$9*G99+Modelo!$B$12*N98+Modelo!$B$13*M99 -> 4.932945 | C99: 5.288267 | D99: -0.86750057 | E99: 4.7397885 | F99: 3.6259397 | G99: -0.12488318 | H99: -2.4595898 | I99: 6.3044488 | J99: 5.0755487 | M99: =M98*O98 -> 11.423969 | N99: =N98 -> 21.581589 | O99: 0.97
A100: 2025q3 | B100: =Modelo!$B$2+Modelo!$B$3*B99+Modelo!$B$4*B98+Modelo!$B$5*C100+Modelo!$B$6*H98+Modelo!$B$7*E101+Modelo!$B$8*D99+Modelo!$B$9*G100+Modelo!$B$12*N99+Modelo!$B$13*M100 -> 4.9483957 | C100: 5.288267 | D100: -0.86750057 | E100: 4.7397885 | F100: 3.6259397 | G100: -0.12488318 | H100: -2.4595898 | I100: 6.3044488 | J100: 5.0755487 | M100: =M99*O99 -> 11.08125 | N100: =N99 -> 21.581589 | O100: 0.97
A101: 2025q4 | B101: =Modelo!$B$2+Modelo!$B$3*B100+Modelo!$B$4*B99+Modelo!$B$5*C101+Modelo!$B$6*H99+Modelo!$B$7*E102+Modelo!$B$8*D100+Modelo!$B$9*G101+Modelo!$B$12*N100+Modelo!$B$13*M101 -> 4.9983849 | C101: 5.288267 | D101: -0.86750057 | E101: 4.7397885 | F101: 3.6259397 | G101: -0.12488318 | H101: -2.4595898 | I101: 6.3044488 | J101: 5.0755487 | M101: =M100*O100 -> 10.748813 | N101: =N100 -> 21.581589 | O101: 0.97
A102: 2026q1 | B102: =Modelo!$B$2+Modelo!$B$3*B101+Modelo!$B$4*B100+Modelo!$B$5*C102+Modelo!$B$6*H100+Modelo!$B$7*E103+Modelo!$B$8*D101+Modelo!$B$9*G102+Modelo!$B$12*N101+Modelo!$B$13*M102 -> 5.037384 | C102: 5.288267 | D102: -0.86750057 | E102: 4.7397885 | F102: 3.6259397 | G102: -0.12488318 | H102: -2.4595898 | I102: 6.3044488 | J102: 5.0755487 | M102: =M101*O101 -> 10.426348 | N102: =N101 -> 21.581589 | O102: 0.97
A103: 2026q2 | B103: =Modelo!$B$2+Modelo!$B$3*B102+Modelo!$B$4*B101+Modelo!$B$5*C103+Modelo!$B$6*H101+Modelo!$B$7*E104+Modelo!$B$8*D102+Modelo!$B$9*G103+Modelo!$B$12*N102+Modelo!$B$13*M103 -> 5.0842322 | C103: 5.288267 | D103: -0.86750057 | E103: 4.7397885 | F103: 3.6259397 | G103: -0.12488318 | H103: -2.4595898 | I103: 6.3044488 | J103: 5.0755487 | M103: =M102*O102 -> 10.113558 | N103: =N102 -> 21.581589 | O103: 0.97
A104: 2026q3 | B104: =Modelo!$B$2+Modelo!$B$3*B103+Modelo!$B$4*B102+Modelo!$B$5*C104+Modelo!$B$6*H102+Modelo!$B$7*E105+Modelo!$B$8*D103+Modelo!$B$9*G104+Modelo!$B$12*N103+Modelo!$B$13*M104 -> 5.1266297 | C104: 5.288267 | D104: -0.86750057 | E104: 4.7397885 | F104: 3.6259397 | G104: -0.12488318 | H104: -2.4595898 | I104: 6.3044488 | J104: 5.0755487 | M104: =M103*O103 -> 9.810151 | N104: =N103 -> 21.581589 | O104: 0.97
A105: 2026q4 | B105: =Modelo!$B$2+Modelo!$B$3*B104+Modelo!$B$4*B103+Modelo!$B$5*C105+Modelo!$B$6*H103+Modelo!$B$7*E106+Modelo!$B$8*D104+Modelo!$B$9*G105+Modelo!$B$12*N104+Modelo!$B$13*M105 -> 5.170135 | C105: 5.288267 | D105: -0.86750057 | E105: 4.7397885 | F105: 3.6259397 | G105: -0.12488318 | H105: -2.4595898 | I105: 6.3044488 | J105: 5.0755487 | M105: =M104*O104 -> 9.5158464 | N105: =N104 -> 21.581589 | O105: 0.97
A106: 2027q1 | B106: =Modelo!$B$2+Modelo!$B$3*B105+Modelo!$B$4*B104+Modelo!$B$5*C106+Modelo!$B$6*H104+Modelo!$B$7*E107+Modelo!$B$8*D105+Modelo!$B$9*G106+Modelo!$B$12*N105+Modelo!$B$13*M106 -> 5.2114059 | C106: 5.288267 | D106: -0.86750057 | E106: 4.7397885 | F106: 3.6259397 | G106: -0.12488318 | H106: -2.4595898 | I106: 6.3044488 | J106: 5.0755487 | M106: =M105*O105 -> 9.2303711 | N106: =N105 -> 21.581589 | O106: 0.97
A107: 2027q2 | B107: =Modelo!$B$2+Modelo!$B$3*B106+Modelo!$B$4*B105+Modelo!$B$5*C107+Modelo!$B$6*H105+Modelo!$B$7*E108+Modelo!$B$8*D106+Modelo!$B$9*G107+Modelo!$B$12*N106+Modelo!$B$13*M107 -> 5.2520783 | C107: 5.288267 | D107: -0.86750057 | E107: 4.7397885 | F107: 3.6259397 | G107: -0.12488318 | H107: -2.4595898 | I107: 6.3044488 | J107: 5.0755487 | M107: =M106*O106 -> 8.9534599 | N107: =N106 -> 21.581589 | O107: 0.97
...

Sheet SP
A1: Data | B1: LCAMBIOREAL | C1: LCDS_5_ANOS | D1: LPASSEXTERNO | E1: LTOTL | F1: LVIXFINAL | G1: LDIVBRUTA | H1: LSWAPREAL | I1: LCRB | J1: LIBCBR | K1: LUSPROD | L1: LRESERVAS | M1: LIBOV | N1: LSeP | O1: D0804 | P1: D1503 | Q1: D2002 | R1: D1301 | S1: D2018 | T1: D2024
A2: 2005Q1 | B2: 4.8131866 | C2: 5.8671571 | D2: -0.88916206 | E2: 4.4534166 | F2: 2.562639 | G2: -0.38345903 | H2: -2.1914966 | I2: 5.6797971 | J2: 4.7041101 | K2: 2.5726122 | L2: 5.6818776 | M2: 10.18908 | N2: 7.0737696 | O2: 0 | P2: 0 | Q2: 0 | R2: 0 | S2: 0 | T2: 0
A3: 2005Q2 | B3: 4.725173 | C3: 5.9302094 | D3: -0.91379385 | E3: 4.4628767 | F3: 2.6063865 | G3: -0.3915622 | H3: -2.1764971 | I3: 5.7000422 | J3: 4.7033852 | K3: 2.5572273 | L3: 5.8030243 | M3: 10.128669 | N3: 7.0828256 | O3: 0 | P3: 0 | Q3: 0 | R3: 0 | S3: 0 | T3: 0
A4: 2005Q3 | B4: 4.6610148 | C4: 5.7666737 | D4: -0.86274996 | E4: 4.4680896 | F4: 2.4874035 | G4: -0.39501985 | H4: -2.1558024 | I4: 5.6796605 | J4: 4.7069142 | K4: 2.5649494 | L4: 5.7695702 | M4: 10.360406 | N4: 7.1138015 | O4: 0 | P4: 0 | Q4: 0 | R4: 0 | S4: 0 | T4: 0
A5: 2005Q4 | B5: 4.6017978 | C5: 5.5740154 | D5: -1.0356375 | E5: 4.472819 | F5: 2.5764218 | G5: -0.39868812 | H5: -2.185336 | I5: 5.6889395 | J5: 4.7267682 | K5: 2.5649494 | L5: 5.695078 | M5: 10.417986 | N5: 7.1295299 | O5: 0 | P5: 0 | Q5: 0 | R5: 0 | S5: 0 | T5: 0
A6: 2006Q1 | B6: 4.5761189 | C6: 5.0431883 | D6: -0.98349948 | E6: 4.488524 | F6: 2.5038919 | G6: -0.40351701 | H6: -2.2145114 | I6: 5.7308787 | J6: 4.7315385 | K6: 2.5726122 | L6: 6.192567 | M6: 10.544077 | N6: 7.1661656 | O6: 0 | P6: 0 | Q6: 0 | R6: 0 | S6: 0 | T6: 0
A7: 2006Q2 | B7: 4.5944462 | C7: 5.0942409 | D7: -1.0671136 | E7: 4.4907689 | F7: 2.6173958 | G7: -0.44498587 | H7: -2.293978 | I7: 5.7809184 | J7: 4.7391765 | K7: 2.5726122 | L7: 6.5537909 | M7: 10.50865 | N7: 7.1469296 | O7: 0 | P7: 0 | Q7: 0 | R7: 0 | S7: 0 | T7: 0
A8: 2006Q3 | B8: 4.6000236 | C8: 4.9247629 | D8: -1.1394343 | E8: 4.5340322 | F8: 2.5710843 | G8: -0.4486336 | H8: -2.4498723 | I8: 5.8269141 | J8: 4.7595208 | K8: 2.5572273 | L8: 6.6000065 | M8: 10.503669 | N8: 7.1973231 | O8: 0 | P8: 0 | Q8: 0 | R8: 0 | S8: 0 | T8: 0
A9: 2006Q4 | B9: 4.5904964 | C9: 4.6999348 | D9: -1.0936247 | E9: 4.550714 | F9: 2.4150205 | G9: -0.44005655 | H9: -2.5099348 | I9: 5.8633565 | J9: 4.7934738 | K9: 2.5572273 | L9: 6.8028391 | M9: 10.70266 | N9: 7.2572143 | O9: 0 | P9: 0 | Q9: 0 | R9: 0 | S9: 0 | T9: 0
A10: 2007Q1 | B10: 4.5707168 | C10: 4.5367128 | D10: -1.1239301 | E10: 4.5594054 | F10: 2.6019487 | G10: -0.44207723 | H10: -2.5717689 | I10: 5.9003265 | J10: 4.783149 | K10: 2.541602 | L10: 6.9899802 | M10: 10.732149 | N10: 7.2590176 | O10: 0 | P10: 0 | Q10: 0 | R10: 0 | S10: 0 | T10: 0
A11: 2007Q2 | B11: 4.5261631 | C11: 4.2427646 | D11: -1.0384584 | E11: 4.5377832 | F11: 2.6741486 | G11: -0.44665175 | H11: -2.6018223 | I11: 5.9733685 | J11: 4.8121844 | K11: 2.5572273 | L11: 7.2953279 | M11: 10.903972 | N11: 7.3154512 | O11: 0 | P11: 0 | Q11: 0 | R11: 0 | S11: 0 | T11: 0
A12: 2007Q3 | B12: 4.5035434 | C12: 4.6039027 | D12: -0.94417594 | E12: 4.5449955 | F12: 3.0740812 | G12: -0.47117765 | H12: -2.6671874 | I12: 6.0096891 | J12: 4.8291134 | K12: 2.5494452 | L12: 7.5298897 | M12: 11.00982 | N12: 7.3308966 | O12: 0 | P12: 0 | Q12: 0 | R12: 0 | S12: 0 | T12: 0
A13: 2007Q4 | B13: 4.458293 | C13: 4.560138 | D13: -0.93649344 | E13: 4.5658401 | F13: 3.0587071 | G13: -0.46251176 | H13: -2.6651851 | I13: 6.0304048 | J13: 4.8490571 | K13: 2.541602 | L13: 7.5591425 | M13: 11.064856 | N13: 7.2919014 | O13: 0 | P13: 0 | Q13: 0 | R13: 0 | S13: 0 | T13: 0
... A81: 2024q4 | B81: 4.9115513 | C81: 5.2832037 | D81: -0.89159812 | E81: 4.7597779 | F81: 2.9724636 | G81: -0.13604884 | H81: -2.512319 | I81: 6.2841342 | J81: 5.0656915 | K81: 2.2925348 | L81: 7.7218361 | M81: 11.697603 | N81: 8.6795892 | O81: 0 | P81: 0 | Q81: 0 | R81: 0 | S81: 0 | T81: 1
A82: 2025q1 | B82: 4.8893712 | C82: 5.288267 | D82: -0.86750057 | E82: 4.7397885 | F82: 3.6259397 | G82: -0.12488318 | H82: -2.4595898 | I82: 6.3044488 | J82: 5.0755487 | K82: 2.2721259 | L82: 7.6349657 | M82: 11.777288 | N82: =8.63263572982787*2.5 -> 21.581589 | O82: 0 | P82: 0 | Q82: 0 | R82: 0 | S82: 0 | T82: 0
A83: 2025q2 | B83: =Modelo!$B$2+Modelo!$B$3*B82+Modelo!$B$4*B81+Modelo!$B$5*C83+Modelo!$B$6*H81+Modelo!$B$7*E84+Modelo!$B$8*D82+Modelo!$B$9*G83+Modelo!$B$12*N83+Modelo!$B$13*M83 -> 4.983858 | C83: 5.288267 | D83: -0.86750057 | E83: 4.7397885 | F83: 3.6259397 | G83: -0.12488318 | H83: -2.4595898 | I83: 6.3044488 | J83: 5.0755487 | M83: 11.777288 | N83: =N82*O84 -> 22.229037
A84: 2025q3 | B84: =Modelo!$B$2+Modelo!$B$3*B83+Modelo!$B$4*B82+Modelo!$B$5*C84+Modelo!$B$6*H82+Modelo!$B$7*E85+Modelo!$B$8*D83+Modelo!$B$9*G84+Modelo!$B$12*N84+Modelo!$B$13*M84 -> 5.0496447 | C84: 5.288267 | D84: -0.86750057 | E84: 4.7397885 | F84: 3.6259397 | G84: -0.12488318 | H84: -2.4595898 | I84: 6.3044488 | J84: 5.0755487 | M84: 11.777288 | N84: =N83*O85 -> 22.895908 | O84: 1.03
A85: 2025q4 | B85: =Modelo!$B$2+Modelo!$B$3*B84+Modelo!$B$4*B83+Modelo!$B$5*C85+Modelo!$B$6*H83+Modelo!$B$7*E86+Modelo!$B$8*D84+Modelo!$B$9*G85+Modelo!$B$12*N85+Modelo!$B$13*M85 -> 5.1660645 | C85: 5.288267 | D85: -0.86750057 | E85: 4.7397885 | F85: 3.6259397 | G85: -0.12488318 | H85: -2.4595898 | I85: 6.3044488 | J85: 5.0755487 | M85: 11.777288 | N85: =N84*O86 -> 23.582785 | O85: 1.03 | S85: =SP!N82*Modelo!B12 -> 3.1601921
A86: 2026q1 | B86: =Modelo!$B$2+Modelo!$B$3*B85+Modelo!$B$4*B84+Modelo!$B$5*C86+Modelo!$B$6*H84+Modelo!$B$7*E87+Modelo!$B$8*D85+Modelo!$B$9*G86+Modelo!$B$12*N86+Modelo!$B$13*M86 -> 5.2741188 | C86: 5.288267 | D86: -0.86750057 | E86: 4.7397885 | F86: 3.6259397 | G86: -0.12488318 | H86: -2.4595898 | I86: 6.3044488 | J86: 5.0755487 | M86: 11.777288 | N86: =N85*O87 -> 24.290269 | O86: 1.03 | S86: =Modelo!B13*SP!M83 -> -1.4630925
A87: 2026q2 | B87: =Modelo!$B$2+Modelo!$B$3*B86+Modelo!$B$4*B85+Modelo!$B$5*C87+Modelo!$B$6*H85+Modelo!$B$7*E88+Modelo!$B$8*D86+Modelo!$B$9*G87+Modelo!$B$12*N87+Modelo!$B$13*M87 -> 5.3978286 | C87: 5.288267 | D87: -0.86750057 | E87: 4.7397885 | F87: 3.6259397 | G87: -0.12488318 | H87: -2.4595898 | I87: 6.3044488 | J87: 5.0755487 | M87: 11.777288 | N87: =N86*O88 -> 25.018977 | O87: 1.03
A88: 2026q3 | B88: =Modelo!$B$2+Modelo!$B$3*B87+Modelo!$B$4*B86+Modelo!$B$5*C88+Modelo!$B$6*H86+Modelo!$B$7*E89+Modelo!$B$8*D87+Modelo!$B$9*G88+Modelo!$B$12*N88+Modelo!$B$13*M88 -> 5.5213382 | C88: 5.288267 | D88: -0.86750057 | E88: 4.7397885 | F88: 3.6259397 | G88: -0.12488318 | H88: -2.4595898 | I88: 6.3044488 | J88: 5.0755487 | M88: 11.777288 | N88: =N87*O89 -> 25.769546 | O88: 1.03
A89: 2026q4 | B89: =Modelo!$B$2+Modelo!$B$3*B88+Modelo!$B$4*B87+Modelo!$B$5*C89+Modelo!$B$6*H87+Modelo!$B$7*E90+Modelo!$B$8*D88+Modelo!$B$9*G89+Modelo!$B$12*N89+Modelo!$B$13*M89 -> 5.6518025 | C89: 5.288267 | D89: -0.86750057 | E89: 4.7397885 | F89: 3.6259397 | G89: -0.12488318 | H89: -2.4595898 | I89: 6.3044488 | J89: 5.0755487 | M89: 11.777288 | N89: =N88*O90 -> 26.542633 | O89: 1.03
A90: 2027q1 | B90: =Modelo!$B$2+Modelo!$B$3*B89+Modelo!$B$4*B88+Modelo!$B$5*C90+Modelo!$B$6*H88+Modelo!$B$7*E91+Modelo!$B$8*D89+Modelo!$B$9*G90+Modelo!$B$12*N90+Modelo!$B$13*M90 -> 5.7849692 | C90: 5.288267 | D90: -0.86750057 | E90: 4.7397885 | F90: 3.6259397 | G90: -0.12488318 | H90: -2.4595898 | I90: 6.3044488 | J90: 5.0755487 | M90: 11.777288 | N90: =N89*O91 -> 27.338912 | O90: 1.03
A91: 2027q2 | B91: =Modelo!$B$2+Modelo!$B$3*B90+Modelo!$B$4*B89+Modelo!$B$5*C91+Modelo!$B$6*H89+Modelo!$B$7*E92+Modelo!$B$8*D90+Modelo!$B$9*G91+Modelo!$B$12*N91+Modelo!$B$13*M91 -> 5.922999 | C91: 5.288267 | D91: -0.86750057 | E91: 4.7397885 | F91: 3.6259397 | G91: -0.12488318 | H91: -2.4595898 | I91: 6.3044488 | J91: 5.0755487 | M91: 11.777288 | N91: =N90*O92 -> 28.159079 | O91: 1.03
A92: 2027q3 | B92: =Modelo!$B$2+Modelo!$B$3*B91+Modelo!$B$4*B90+Modelo!$B$5*C92+Modelo!$B$6*H90+Modelo!$B$7*E93+Modelo!$B$8*D91+Modelo!$B$9*G92+Modelo!$B$12*N92+Modelo!$B$13*M92 -> 6.0648072 | C92: 5.288267 | D92: -0.86750057 | E92: 4.7397885 | F92: 3.6259397 | G92: -0.12488318 | H92: -2.4595898 | I92: 6.3044488 | J92: 5.0755487 | M92: 11.777288 | N92: =N91*O93 -> 29.003851 | O92: 1.03
A93: 2027q4 | B93: =Modelo!$B$2+Modelo!$B$3*B92+Modelo!$B$4*B91+Modelo!$B$5*C93+Modelo!$B$6*H91+Modelo!$B$7*E94+Modelo!$B$8*D92+Modelo!$B$9*G93+Modelo!$B$12*N93+Modelo!$B$13*M93 -> 6.2111052 | C93: 5.288267 | D93: -0.86750057 | E93: 4.7397885 | F93: 3.6259397 | G93: -0.12488318 | H93: -2.4595898 | I93: 6.3044488 | J93: 5.0755487 | M93: 11.777288 | N93: =N92*O93 -> 29.873967 | O93: 1.03
E94: 4.7397885
A95: 2024q2 | B95: 4.8081927 | C95: 4.9767337 | D95: -0.86750057 | E95: 4.7126784 | F95: 2.5063419 | G95: -0.13284591 | H95: -2.7257051 | I95: 6.2897156 | J95: 5.0456806 | K95: 2.3025851 | L95: 7.6979384 | M95: 11.727287 | N95: 8.605292
A96: 2024q3 | B96: 4.8917016 | C96: 5.0434251 | D96: -0.83240925 | E96: 4.7376886 | F96: 3.0184718 | G96: -0.16369609 | H96: -2.6333139 | I96: 6.2915691 | J96: 5.0557361 | K96: 2.3025851 | L96: 7.7214373 | M96: 11.789162 | N96: 8.6591232
A97: 2024q4 | B97: 4.9115513 | C97: 5.2832037 | D97: -0.89159812 | E97: 4.7597779 | F97: 2.9724636 | G97: -0.13604884 | H97: -2.512319 | I97: 6.2841342 | J97: 5.0656915 | K97: 2.2925348 | L97: 7.7218361 | M97: 11.697603 | N97: 8.6795892
A98: 2025q1 | B98: 4.8893712 | C98: 5.288267 | D98: -0.86750057 | E98: 4.7397885 | F98: 3.6259397 | G98: -0.12488318 | H98: -2.4595898 | I98: 6.3044488 | J98: 5.0755487 | K98: 2.2721259 | L98: 7.6349657 | M98: 11.777288 | N98: =8.63263572982787*2.5 -> 21.581589 | O98: 0.97
A99: 2025q2 | B99: =Modelo!$B$2+Modelo!$B$3*B98+Modelo!$B$4*B97+Modelo!$B$5*C99+Modelo!$B$6*H97+Modelo!$B$7*E100+Modelo!$B$8*D98+Modelo!$B$9*G99+Modelo!$B$12*N99+Modelo!$B$13*M99 -> 4.7942465 | C99: 5.288267 | D99: -0.86750057 | E99: 4.7397885 | F99: 3.6259397 | G99: -0.12488318 | H99: -2.4595898 | I99: 6.3044488 | J99: 5.0755487 | M99: 11.777288 | N99: =N98*O100 -> 20.934142 | O99: 0.97
A100: 2025q3 | B100: =Modelo!$B$2+Modelo!$B$3*B99+Modelo!$B$4*B98+Modelo!$B$5*C100+Modelo!$B$6*H98+Modelo!$B$7*E101+Modelo!$B$8*D99+Modelo!$B$9*G100+Modelo!$B$12*N100+Modelo!$B$13*M100 -> 4.6880669 | C100: 5.288267 | D100: -0.86750057 | E100: 4.7397885 | F100: 3.6259397 | G100: -0.12488318 | H100: -2.4595898 | I100: 6.3044488 | J100: 5.0755487 | M100: 11.777288 | N100: =N99*O101 -> 20.306117 | O100: 0.97
A101: 2025q4 | B101: =Modelo!$B$2+Modelo!$B$3*B100+Modelo!$B$4*B99+Modelo!$B$5*C101+Modelo!$B$6*H99+Modelo!$B$7*E102+Modelo!$B$8*D100+Modelo!$B$9*G101+Modelo!$B$12*N101+Modelo!$B$13*M101 -> 4.5866344 | C101: 5.288267 | D101: -0.86750057 | E101: 4.7397885 | F101: 3.6259397 | G101: -0.12488318 | H101: -2.4595898 | I101: 6.3044488 | J101: 5.0755487 | M101: 11.777288 | N101: =N100*O102 -> 19.696934 | O101: 0.97
A102: 2026q1 | B102: =Modelo!$B$2+Modelo!$B$3*B101+Modelo!$B$4*B100+Modelo!$B$5*C102+Modelo!$B$6*H100+Modelo!$B$7*E103+Modelo!$B$8*D101+Modelo!$B$9*G102+Modelo!$B$12*N102+Modelo!$B$13*M102 -> 4.4848667 | C102: 5.288267 | D102: -0.86750057 | E102: 4.7397885 | F102: 3.6259397 | G102: -0.12488318 | H102: -2.4595898 | I102: 6.3044488 | J102: 5.0755487 | M102: 11.777288 | N102: =N101*O103 -> 19.106026 | O102: 0.97
A103: 2026q2 | B103: =Modelo!$B$2+Modelo!$B$3*B102+Modelo!$B$4*B101+Modelo!$B$5*C103+Modelo!$B$6*H101+Modelo!$B$7*E104+Modelo!$B$8*D102+Modelo!$B$9*G103+Modelo!$B$12*N103+Modelo!$B$13*M103 -> 4.3868294 | C103: 5.288267 | D103: -0.86750057 | E103: 4.7397885 | F103: 3.6259397 | G103: -0.12488318 | H103: -2.4595898 | I103: 6.3044488 | J103: 5.0755487 | M103: 11.777288 | N103: =N102*O104 -> 18.532845 | O103: 0.97
A104: 2026q3 | B104: =Modelo!$B$2+Modelo!$B$3*B103+Modelo!$B$4*B102+Modelo!$B$5*C104+Modelo!$B$6*H102+Modelo!$B$7*E105+Modelo!$B$8*D103+Modelo!$B$9*G104+Modelo!$B$12*N104+Modelo!$B$13*M104 -> 4.2908849 | C104: 5.288267 | D104: -0.86750057 | E104: 4.7397885 | F104: 3.6259397 | G104: -0.12488318 | H104: -2.4595898 | I104: 6.3044488 | J104: 5.0755487 | M104: 11.777288 | N104: =N103*O105 -> 17.97686 | O104: 0.97
A105: 2026q4 | B105: =Modelo!$B$2+Modelo!$B$3*B104+Modelo!$B$4*B103+Modelo!$B$5*C105+Modelo!$B$6*H103+Modelo!$B$7*E106+Modelo!$B$8*D104+Modelo!$B$9*G105+Modelo!$B$12*N105+Modelo!$B$13*M105 -> 4.1980552 | C105: 5.288267 | D105: -0.86750057 | E105: 4.7397885 | F105: 3.6259397 | G105: -0.12488318 | H105: -2.4595898 | I105: 6.3044488 | J105: 5.0755487 | M105: 11.777288 | N105: =N104*O106 -> 17.437554 | O105: 0.97
A106: 2027q1 | B106: =Modelo!$B$2+Modelo!$B$3*B105+Modelo!$B$4*B104+Modelo!$B$5*C106+Modelo!$B$6*H104+Modelo!$B$7*E107+Modelo!$B$8*D105+Modelo!$B$9*G106+Modelo!$B$12*N106+Modelo!$B$13*M106 -> 4.1077911 | C106: 5.288267 | D106: -0.86750057 | E106: 4.7397885 | F106: 3.6259397 | G106: -0.12488318 | H106: -2.4595898 | I106: 6.3044488 | J106: 5.0755487 | M106: 11.777288 | N106: =N105*O107 -> 16.914427 | O106: 0.97
A107: 2027q2 | B107: =Modelo!$B$2+Modelo!$B$3*B106+Modelo!$B$4*B105+Modelo!$B$5*C107+Modelo!$B$6*H105+Modelo!$B$7*E108+Modelo!$B$8*D106+Modelo!$B$9*G107+Modelo!$B$12*N107+Modelo!$B$13*M107 -> 4.0203104 | C107: 5.288267 | D107: -0.86750057 | E107: 4.7397885 | F107: 3.6259397 | G107: -0.12488318 | H107: -2.4595898 | I107: 6.3044488 | J107: 5.0755487 | M107: 11.777288 | N107: =N106*O108 -> 16.406994 | O107: 0.97
...

Sheet Modelo
A2: C | B2: =2.14104 -> 2.14104
A3: Lcambior1 | B3: =-0.09306 -> -0.09306
A4: Lcambior2 | B4: =0.23244 -> 0.23244
A5: cds | B5: =-0.01232 -> -0.01232
A6: Lsawp2 | B6: =-0.33975 -> -0.33975
A7: Ltots(-1) | B7: =-0.08648 -> -0.08648
A8: Lpasse1 | B8: =-0.0103 -> -0.0103
A9: div | B9: =0.18554 -> 0.18554
A10: D0804 | B10: =0.17657 -> 0.17657
A11: D1503 | B11: =0.08289 -> 0.08289
A12: sep | B12: =0.14643 -> 0.14643
A13: ibov | B13: =-0.12423 -> -0.12423
