Workbook

Sheet Dados
A1: observation_date | B1: FEDFUNDS | C1: SELIC | D1: CAMBIO | E1: CDS_5 | F1: CRB | G1: DXY | H1: VIX | I1: IPCA | J1: CPI | K1: IGP-M | L1: swapreal360
A2: 37257 | B2: 1.73 | C2: 19.05 | D2: 2.418 | E2: 812.39 | F2: 212.32 | G2: 120.21 | H2: 21.09 | I2: 4.76 | J2: 3.5575 | K2: 0.36 | L2: 0
A3: 37288 | B3: 1.74 | C3: 18.97 | D3: 2.348 | E3: 829.44 | F3: 215.88 | G3: 119.16 | H3: 21.59 | I3: 4.7 | J3: 3.5274 | K3: 0.06 | L3: 0
A4: 37316 | B4: 1.73 | C4: 18.72 | D4: 2.324 | E4: 739.36 | F4: 219.64 | G4: 118.62 | H4: 17.4 | I4: 4.94 | J4: 3.4685 | K4: 0.09 | L4: 0
A5: 37347 | B5: 1.75 | C5: 18.38 | D5: 2.363 | E5: 753.11 | F5: 212.94 | G5: 115.19 | H5: 21.91 | I5: 4.9 | J5: 3.4658 | K5: 0.56 | L5: 0
A6: 37377 | B6: 1.75 | C6: 18.37 | D6: 2.522 | E6: 996.21 | F6: 221.95 | G6: 111.81 | H6: 19.98 | I6: 4.37 | J6: 3.4521 | K6: 0.83 | L6: 0
A7: 37408 | B7: 1.75 | C7: 18.1 | D7: 2.844 | E7: 1647.44 | F7: 232.95 | G7: 106.11 | H7: 25.4 | I7: 4.57 | J7: 3.2417 | K7: 1.54 | L7: 0.17066
A8: 37438 | B8: 1.73 | C8: 18.17 | D8: 3.429 | E8: 2436.3 | F8: 234.1 | G8: 107.41 | H8: 32.03 | I8: 5.08 | J8: 3.2637 | K8: 1.95 | L8: 0.166183
A9: 37469 | B9: 1.74 | C9: 17.84 | D9: 3.022 | E9: 2965.8 | F9: 233.22 | G9: 106.98 | H9: 32.64 | I9: 5.4 | J9: 3.1466 | K9: 2.32 | L9: 0.158207
A10: 37500 | B10: 1.75 | C10: 17.89 | D10: 3.895 | E10: 3139.83 | F10: 237.21 | G10: 106.87 | H10: 39.69 | I10: 6.28 | J10: 3.0266 | K10: 2.4 | L10: 0.172585
A11: 37530 | B11: 1.75 | C11: 19.59 | D11: 3.645 | E11: 3560.83 | F11: 236.36 | G11: 106.64 | H11: 31.14 | I11: 8.94 | J11: 2.9372 | K11: 3.87 | L11: 0.174265
A12: 37561 | B12: 1.34 | C12: 21.25 | D12: 3.637 | E12: 2840.95 | F12: 241.33 | G12: 106.38 | H12: 27.5 | I12: 12.47 | J12: 2.8243 | K12: 5.19 | L12: 0.150216
A13: 37591 | B13: 1.24 | C13: 23.03 | D13: 3.533 | E13: 2471.14 | F13: 244.31 | G13: 101.85 | H13: 28.62 | I13: 13.24 | J13: 2.7922 | K13: 3.75 | L13: 0.120637
... A283: 45809 | B283: 4.33 | C283: 14.74 | D283: 5.51 | E283: 156 | F283: 561 | G283: 98.49 | H283: 20.21 | I283: 4.88 | J283: 3.1591 | K283: -1.67 | L283: 0.092797

Sheet FED
A1: fixar | B1: FEDFUNDS | C1: SELIC | D1: CAMBIO | E1: CDS_5 | F1: CRB | G1: DXY | H1: VIX | I1: IPCA | J1: CPI | K1: IGP-M | L1: INDINCERT | M1: dfi1
A2: 44927 | B2: 4.33 | C2: 13.65 | D2: 5.08 | E2: 226 | F2: 557.02 | G2: 102 | H2: 18.7 | I2: 5.71 | J2: 6.4883 | K2: 0.21 | L2: 113.3 | M2: =C2-B2 -> 9.32
A3: 44958 | B3: 4.57 | C3: 13.65 | D3: 5.17 | E3: 228 | F3: 548.53 | G3: 101 | H3: 25 | I3: 5.77 | J3: 6.5266 | K3: -0.06 | L3: 111.7 | M3: =C3-B3 -> 9.08
A4: 44986 | B4: 4.65 | C4: 13.65 | D4: 5.06 | E4: 225 | F4: 550.63 | G4: 101.7 | H4: 17 | I4: 5.55 | J4: 6.3906 | K4: 0.05 | L4: 116.7 | M4: =C4-B4 -> 9
A5: 45017 | B5: 4.83 | C5: 13.65 | D5: 4.98 | E5: 220 | F5: 547.45 | G5: 102 | H5: 17 | I5: 5.28 | J5: 6.2677 | K5: -0.95 | L5: 112.6 | M5: =C5-B5 -> 8.82
A6: 45047 | B6: 5.06 | C6: 13.65 | D6: 4.98 | E6: 206 | F6: 541.45 | G6: 104.2 | H6: 16.9 | I6: 4.69 | J6: 5.9789 | K6: -1.84 | L6: 111.8 | M6: =C6-B6 -> 8.59
A7: 45078 | B7: 5.08 | C7: 13.65 | D7: 4.83 | E7: 177 | F7: 547.83 | G7: 103 | H7: 16 | I7: 3.99 | J7: 5.5888 | K7: -1.93 | L7: 107.6 | M7: =C7-B7 -> 8.57
A8: 45108 | B8: 5.12 | C8: 13.65 | D8: 4.71 | E8: 162 | F8: 563.85 | G8: 102 | H8: 14.8 | I8: 4.09 | J8: 5.4029 | K8: -0.72 | L8: 103.5 | M8: =C8-B8 -> 8.53
A9: 45139 | B9: 5.33 | C9: 13.19 | D9: 4.89 | E9: 166 | F9: 552.84 | G9: 105 | H9: 13.8 | I9: 4.22 | J9: 5.1697 | K9: -0.14 | L9: 108.5 | M9: =C9-B9 -> 7.86
A10: 45170 | B10: 5.33 | C10: 12.97 | D10: 5.05 | E10: 186 | F10: 548.56 | G10: 106.6 | H10: 19 | I10: 4.11 | J10: 4.9554 | K10: 0.37 | L10: 106.8 | M10: =C10-B10 -> 7.64
A11: 45200 | B11: 5.33 | C11: 12.65 | D11: 5 | E11: 183 | F11: 539.51 | G11: 105.8 | H11: 14.7 | I11: 3.92 | J11: 4.8827 | K11: 0.5 | L11: 110.9 | M11: =C11-B11 -> 7.32
A12: 45231 | B12: 5.33 | C12: 12.17 | D12: 4.9 | E12: 146 | F12: 529.9 | G12: 104 | H12: 12.3 | I12: 3.92 | J12: 4.6913 | K12: 0.59 | L12: 110.4 | M12: =C12-B12 -> 6.84
A13: 45261 | B13: 5.33 | C13: 11.87 | D13: 4.85 | E13: 131 | F13: 510.32 | G13: 102.4 | H13: 12.7 | I13: 3.81 | J13: 4.5577 | K13: 0.74 | L13: 107 | M13: =C13-B13 -> 6.54
... A30: 45778 | B30: 4.33 | C30: 14.55 | D30: 5.72 | E30: 160 | F30: 555.02 | G30: 99 | H30: 18.57 | I30: 4.86 | J30: 3.1591 | K30: -0.49 | L30: 112.8 | M30: =C30-B30 -> 10.22
A31: 45809 | B31: 4.33 | C31: 14.74 | D31: 5.51 | E31: 156 | F31: 561 | G31: 98.49 | H31: 20.21 | I31: 4.88 | J31: 3.1591 | K31: -1.67 | L31: 112 | M31: =C31-B31 -> 10.41 | O31: 1
A32: 45839 | B32: =B31*O32 -> 4.4599 | C32: 14.74 | D32: =EXP(LN(D31)+Modelo!$C$5*(LN(F32)-LN(F31))+Modelo!$C$6*(LN(H32)-LN(H31))+Modelo!$C$7*(LN(E32)-LN(E31))+Modelo!$C$8*(LN(G32)-LN(G31))+Modelo!$C$9*(LN(L32)-LN(L31))+Modelo!$C$10*(LN(C32)-LN(C31))+Modelo!$C$11*(LN(B32)-LN(B31))+Modelo!$C$11*(M32-M31)+ Modelo!$C$13) -> 5.5812345 | E32: 150 | F32: 550 | G32: 97 | H32: 19 | L32: 112 | M32: =C32-B32 -> 10.2801 | O32: 1.03 | P32: 0.97
A33: 45870 | B33: =B32*O33 -> 4.593697 | C33: 14.74 | D33: =EXP(LN(D32)+Modelo!$C$5*(LN(F33)-LN(F32))+Modelo!$C$6*(LN(H33)-LN(H32))+Modelo!$C$7*(LN(E33)-LN(E32))+Modelo!$C$8*(LN(G33)-LN(G32))+Modelo!$C$9*(LN(L33)-LN(L32))+Modelo!$C$10*(LN(C33)-LN(C32))+Modelo!$C$11*(LN(B33)-LN(B32))+Modelo!$C$11*(M33-M32)+ Modelo!$C$13) -> 5.6808291 | E33: 150 | F33: 550 | G33: 97 | H33: 19 | L33: 112 | M33: =C33-B33 -> 10.146303 | O33: 1.03 | P33: 0.97
A34: 45901 | B34: =B33*O34 -> 4.7315079 | C34: 14.74 | D34: =EXP(LN(D33)+Modelo!$C$5*(LN(F34)-LN(F33))+Modelo!$C$6*(LN(H34)-LN(H33))+Modelo!$C$7*(LN(E34)-LN(E33))+Modelo!$C$8*(LN(G34)-LN(G33))+Modelo!$C$9*(LN(L34)-LN(L33))+Modelo!$C$10*(LN(C34)-LN(C33))+Modelo!$C$11*(LN(B34)-LN(B33))+Modelo!$C$11*(M34-M33)+ Modelo!$C$13) -> 5.7826205 | E34: 150 | F34: 550 | G34: 97 | H34: 19 | L34: 112 | M34: =C34-B34 -> 10.008492 | O34: 1.03 | P34: 0.97
A35: 45931 | B35: =B34*O35 -> 4.8734531 | C35: 14.74 | D35: =EXP(LN(D34)+Modelo!$C$5*(LN(F35)-LN(F34))+Modelo!$C$6*(LN(H35)-LN(H34))+Modelo!$C$7*(LN(E35)-LN(E34))+Modelo!$C$8*(LN(G35)-LN(G34))+Modelo!$C$9*(LN(L35)-LN(L34))+Modelo!$C$10*(LN(C35)-LN(C34))+Modelo!$C$11*(LN(B35)-LN(B34))+Modelo!$C$11*(M35-M34)+ Modelo!$C$13) -> 5.8866758 | E35: 150 | F35: 550 | G35: 97 | H35: 19 | L35: 112 | M35: =C35-B35 -> 9.8665469 | O35: 1.03 | P35: 0.97
A36: 45962 | B36: =B35*O36 -> 5.0196567 | C36: 14.74 | D36: =EXP(LN(D35)+Modelo!$C$5*(LN(F36)-LN(F35))+Modelo!$C$6*(LN(H36)-LN(H35))+Modelo!$C$7*(LN(E36)-LN(E35))+Modelo!$C$8*(LN(G36)-LN(G35))+Modelo!$C$9*(LN(L36)-LN(L35))+Modelo!$C$10*(LN(C36)-LN(C35))+Modelo!$C$11*(LN(B36)-LN(B35))+Modelo!$C$11*(M36-M35)+ Modelo!$C$13) -> 5.9930648 | E36: 150 | F36: 550 | G36: 97 | H36: 19 | L36: 112 | M36: =C36-B36 -> 9.7203433 | O36: 1.03 | P36: 0.97
A37: 45992 | B37: =B36*O37 -> 5.1702464 | C37: 14.74 | D37: =EXP(LN(D36)+Modelo!$C$5*(LN(F37)-LN(F36))+Modelo!$C$6*(LN(H37)-LN(H36))+Modelo!$C$7*(LN(E37)-LN(E36))+Modelo!$C$8*(LN(G37)-LN(G36))+Modelo!$C$9*(LN(L37)-LN(L36))+Modelo!$C$10*(LN(C37)-LN(C36))+Modelo!$C$11*(LN(B37)-LN(B36))+Modelo!$C$11*(M37-M36)+ Modelo!$C$13) -> 6.1018602 | E37: 150 | F37: 550 | G37: 97 | H37: 19 | L37: 112 | M37: =C37-B37 -> 9.5697536 | O37: 1.03 | P37: 0.97
A38: 46023 | B38: =B37*O38 -> 5.3253538 | C38: 14.74 | D38: =EXP(LN(D37)+Modelo!$C$5*(LN(F38)-LN(F37))+Modelo!$C$6*(LN(H38)-LN(H37))+Modelo!$C$7*(LN(E38)-LN(E37))+Modelo!$C$8*(LN(G38)-LN(G37))+Modelo!$C$9*(LN(L38)-LN(L37))+Modelo!$C$10*(LN(C38)-LN(C37))+Modelo!$C$11*(LN(B38)-LN(B37))+Modelo!$C$11*(M38-M37)+ Modelo!$C$13) -> 6.2131381 | E38: 150 | F38: 550 | G38: 97 | H38: 19 | L38: 112 | M38: =C38-B38 -> 9.4146462 | O38: 1.03 | P38: 0.97
A39: 46054 | B39: =B38*O39 -> 5.4851145 | C39: 14.74 | D39: =EXP(LN(D38)+Modelo!$C$5*(LN(F39)-LN(F38))+Modelo!$C$6*(LN(H39)-LN(H38))+Modelo!$C$7*(LN(E39)-LN(E38))+Modelo!$C$8*(LN(G39)-LN(G38))+Modelo!$C$9*(LN(L39)-LN(L38))+Modelo!$C$10*(LN(C39)-LN(C38))+Modelo!$C$11*(LN(B39)-LN(B38))+Modelo!$C$11*(M39-M38)+ Modelo!$C$13) -> 6.3269775 | E39: 150 | F39: 550 | G39: 97 | H39: 19 | L39: 112 | M39: =C39-B39 -> 9.2548855 | O39: 1.03 | P39: 0.97
A40: 46082 | B40: =B39*O40 -> 5.6496679 | C40: 14.74 | D40: =EXP(LN(D39)+Modelo!$C$5*(LN(F40)-LN(F39))+Modelo!$C$6*(LN(H40)-LN(H39))+Modelo!$C$7*(LN(E40)-LN(E39))+Modelo!$C$8*(LN(G40)-LN(G39))+Modelo!$C$9*(LN(L40)-LN(L39))+Modelo!$C$10*(LN(C40)-LN(C39))+Modelo!$C$11*(LN(B40)-LN(B39))+Modelo!$C$11*(M40-M39)+ Modelo!$C$13) -> 6.4434608 | E40: 150 | F40: 550 | G40: 97 | H40: 19 | L40: 112 | M40: =C40-B40 -> 9.0903321 | O40: 1.03 | P40: 0.97
A41: 46113 | B41: =B40*O41 -> 5.8191579 | C41: 14.74 | D41: =EXP(LN(D40)+Modelo!$C$5*(LN(F41)-LN(F40))+Modelo!$C$6*(LN(H41)-LN(H40))+Modelo!$C$7*(LN(E41)-LN(E40))+Modelo!$C$8*(LN(G41)-LN(G40))+Modelo!$C$9*(LN(L41)-LN(L40))+Modelo!$C$10*(LN(C41)-LN(C40))+Modelo!$C$11*(LN(B41)-LN(B40))+Modelo!$C$11*(M41-M40)+ Modelo!$C$13) -> 6.5626743 | E41: 150 | F41: 550 | G41: 97 | H41: 19 | L41: 112 | M41: =C41-B41 -> 8.9208421 | O41: 1.03 | P41: 0.97
A42: 46143 | B42: =B41*O42 -> 5.9937327 | C42: 14.74 | D42: =EXP(LN(D41)+Modelo!$C$5*(LN(F42)-LN(F41))+Modelo!$C$6*(LN(H42)-LN(H41))+Modelo!$C$7*(LN(E42)-LN(E41))+Modelo!$C$8*(LN(G42)-LN(G41))+Modelo!$C$9*(LN(L42)-LN(L41))+Modelo!$C$10*(LN(C42)-LN(C41))+Modelo!$C$11*(LN(B42)-LN(B41))+Modelo!$C$11*(M42-M41)+ Modelo!$C$13) -> 6.6847078 | E42: 150 | F42: 550 | G42: 97 | H42: 19 | L42: 112 | M42: =C42-B42 -> 8.7462673 | O42: 1.03 | P42: 0.97
A43: 46174 | B43: =B42*O43 -> 6.1735446 | C43: 14.74 | D43: =EXP(LN(D42)+Modelo!$C$5*(LN(F43)-LN(F42))+Modelo!$C$6*(LN(H43)-LN(H42))+Modelo!$C$7*(LN(E43)-LN(E42))+Modelo!$C$8*(LN(G43)-LN(G42))+Modelo!$C$9*(LN(L43)-LN(L42))+Modelo!$C$10*(LN(C43)-LN(C42))+Modelo!$C$11*(LN(B43)-LN(B42))+Modelo!$C$11*(M43-M42)+ Modelo!$C$13) -> 6.8096551 | E43: 150 | F43: 550 | G43: 97 | H43: 19 | L43: 112 | M43: =C43-B43 -> 8.5664554 | O43: 1.03 | P43: 0.97
... A49: 46357 | B49: =B48*O49 -> 7.3715352 | C49: 14.74 | D49: =EXP(LN(D48)+Modelo!$C$5*(LN(F49)-LN(F48))+Modelo!$C$6*(LN(H49)-LN(H48))+Modelo!$C$7*(LN(E49)-LN(E48))+Modelo!$C$8*(LN(G49)-LN(G48))+Modelo!$C$9*(LN(L49)-LN(L48))+Modelo!$C$10*(LN(C49)-LN(C48))+Modelo!$C$11*(LN(B49)-LN(B48))+Modelo!$C$11*(M49-M48)+ Modelo!$C$13) -> 7.6263436 | E49: 150 | F49: 550 | G49: 97 | H49: 19 | L49: 112 | M49: =C49-B49 -> 7.3684648 | O49: 1.03 | P49: 0.97
O50: 1.03 | P50: 0.97
A51: 45809 | B51: 4.33 | C51: 14.74 | D51: 5.51 | E51: 156 | F51: 561 | G51: 98.49 | H51: 20.21 | I51: 4.88 | J51: 3.1591 | K51: -1.67 | L51: 112 | M51: =C51-B51 -> 10.41
A52: 45839 | B52: =B51*P32 -> 4.2001 | C52: 14.74 | D52: =EXP(LN(D51)+Modelo!$C$5*(LN(F52)-LN(F51))+Modelo!$C$6*(LN(H52)-LN(H51))+Modelo!$C$7*(LN(E52)-LN(E51))+Modelo!$C$8*(LN(G52)-LN(G51))+Modelo!$C$9*(LN(L52)-LN(L51))+Modelo!$C$10*(LN(C52)-LN(C51))+Modelo!$C$11*(LN(B52)-LN(B51))+Modelo!$C$11*(M52-M51)+ Modelo!$C$13) -> 5.5611155 | E52: 150 | F52: 550 | G52: 97 | H52: 19 | L52: 112 | M52: =C52-B52 -> 10.5399
A53: 45870 | B53: =B52*P33 -> 4.074097 | C53: 14.74 | D53: =EXP(LN(D52)+Modelo!$C$5*(LN(F53)-LN(F52))+Modelo!$C$6*(LN(H53)-LN(H52))+Modelo!$C$7*(LN(E53)-LN(E52))+Modelo!$C$8*(LN(G53)-LN(G52))+Modelo!$C$9*(LN(L53)-LN(L52))+Modelo!$C$10*(LN(C53)-LN(C52))+Modelo!$C$11*(LN(B53)-LN(B52))+Modelo!$C$11*(M53-M52)+ Modelo!$C$13) -> 5.639947 | E53: 150 | F53: 550 | G53: 97 | H53: 19 | L53: 112 | M53: =C53-B53 -> 10.665903
A54: 45901 | B54: =B53*P34 -> 3.9518741 | C54: 14.74 | D54: =EXP(LN(D53)+Modelo!$C$5*(LN(F54)-LN(F53))+Modelo!$C$6*(LN(H54)-LN(H53))+Modelo!$C$7*(LN(E54)-LN(E53))+Modelo!$C$8*(LN(G54)-LN(G53))+Modelo!$C$9*(LN(L54)-LN(L53))+Modelo!$C$10*(LN(C54)-LN(C53))+Modelo!$C$11*(LN(B54)-LN(B53))+Modelo!$C$11*(M54-M53)+ Modelo!$C$13) -> 5.7202869 | E54: 150 | F54: 550 | G54: 97 | H54: 19 | L54: 112 | M54: =C54-B54 -> 10.788126
A55: 45931 | B55: =B54*P35 -> 3.8333179 | C55: 14.74 | D55: =EXP(LN(D54)+Modelo!$C$5*(LN(F55)-LN(F54))+Modelo!$C$6*(LN(H55)-LN(H54))+Modelo!$C$7*(LN(E55)-LN(E54))+Modelo!$C$8*(LN(G55)-LN(G54))+Modelo!$C$9*(LN(L55)-LN(L54))+Modelo!$C$10*(LN(C55)-LN(C54))+Modelo!$C$11*(LN(B55)-LN(B54))+Modelo!$C$11*(M55-M54)+ Modelo!$C$13) -> 5.8021557 | E55: 150 | F55: 550 | G55: 97 | H55: 19 | L55: 112 | M55: =C55-B55 -> 10.906682
A56: 45962 | B56: =B55*P36 -> 3.7183183 | C56: 14.74 | D56: =EXP(LN(D55)+Modelo!$C$5*(LN(F56)-LN(F55))+Modelo!$C$6*(LN(H56)-LN(H55))+Modelo!$C$7*(LN(E56)-LN(E55))+Modelo!$C$8*(LN(G56)-LN(G55))+Modelo!$C$9*(LN(L56)-LN(L55))+Modelo!$C$10*(LN(C56)-LN(C55))+Modelo!$C$11*(LN(B56)-LN(B55))+Modelo!$C$11*(M56-M55)+ Modelo!$C$13) -> 5.8855745 | E56: 150 | F56: 550 | G56: 97 | H56: 19 | L56: 112 | M56: =C56-B56 -> 11.021682
A57: 45992 | B57: =B56*P37 -> 3.6067688 | C57: 14.74 | D57: =EXP(LN(D56)+Modelo!$C$5*(LN(F57)-LN(F56))+Modelo!$C$6*(LN(H57)-LN(H56))+Modelo!$C$7*(LN(E57)-LN(E56))+Modelo!$C$8*(LN(G57)-LN(G56))+Modelo!$C$9*(LN(L57)-LN(L56))+Modelo!$C$10*(LN(C57)-LN(C56))+Modelo!$C$11*(LN(B57)-LN(B56))+Modelo!$C$11*(M57-M56)+ Modelo!$C$13) -> 5.9705651 | E57: 150 | F57: 550 | G57: 97 | H57: 19 | L57: 112 | M57: =C57-B57 -> 11.133231
A58: 46023 | B58: =B57*P38 -> 3.4985657 | C58: 14.74 | D58: =EXP(LN(D57)+Modelo!$C$5*(LN(F58)-LN(F57))+Modelo!$C$6*(LN(H58)-LN(H57))+Modelo!$C$7*(LN(E58)-LN(E57))+Modelo!$C$8*(LN(G58)-LN(G57))+Modelo!$C$9*(LN(L58)-LN(L57))+Modelo!$C$10*(LN(C58)-LN(C57))+Modelo!$C$11*(LN(B58)-LN(B57))+Modelo!$C$11*(M58-M57)+ Modelo!$C$13) -> 6.0571493 | E58: 150 | F58: 550 | G58: 97 | H58: 19 | L58: 112 | M58: =C58-B58 -> 11.241434
A59: 46054 | B59: =B58*P39 -> 3.3936087 | C59: 14.74 | D59: =EXP(LN(D58)+Modelo!$C$5*(LN(F59)-LN(F58))+Modelo!$C$6*(LN(H59)-LN(H58))+Modelo!$C$7*(LN(E59)-LN(E58))+Modelo!$C$8*(LN(G59)-LN(G58))+Modelo!$C$9*(LN(L59)-LN(L58))+Modelo!$C$10*(LN(C59)-LN(C58))+Modelo!$C$11*(LN(B59)-LN(B58))+Modelo!$C$11*(M59-M58)+ Modelo!$C$13) -> 6.1453497 | E59: 150 | F59: 550 | G59: 97 | H59: 19 | L59: 112 | M59: =C59-B59 -> 11.346391
A60: 46082 | B60: =B59*P40 -> 3.2918005 | C60: 14.74 | D60: =EXP(LN(D59)+Modelo!$C$5*(LN(F60)-LN(F59))+Modelo!$C$6*(LN(H60)-LN(H59))+Modelo!$C$7*(LN(E60)-LN(E59))+Modelo!$C$8*(LN(G60)-LN(G59))+Modelo!$C$9*(LN(L60)-LN(L59))+Modelo!$C$10*(LN(C60)-LN(C59))+Modelo!$C$11*(LN(B60)-LN(B59))+Modelo!$C$11*(M60-M59)+ Modelo!$C$13) -> 6.2351894 | E60: 150 | F60: 550 | G60: 97 | H60: 19 | L60: 112 | M60: =C60-B60 -> 11.4482
A61: 46113 | B61: =B60*P41 -> 3.1930465 | C61: 14.74 | D61: =EXP(LN(D60)+Modelo!$C$5*(LN(F61)-LN(F60))+Modelo!$C$6*(LN(H61)-LN(H60))+Modelo!$C$7*(LN(E61)-LN(E60))+Modelo!$C$8*(LN(G61)-LN(G60))+Modelo!$C$9*(LN(L61)-LN(L60))+Modelo!$C$10*(LN(C61)-LN(C60))+Modelo!$C$11*(LN(B61)-LN(B60))+Modelo!$C$11*(M61-M60)+ Modelo!$C$13) -> 6.3266916 | E61: 150 | F61: 550 | G61: 97 | H61: 19 | L61: 112 | M61: =C61-B61 -> 11.546954
...

Sheet Selic
A1: fixar | B1: FEDFUNDS | C1: SELIC | D1: CAMBIO | E1: CDS_5 | F1: CRB | G1: DXY | H1: VIX | I1: IPCA | J1: CPI | K1: IGP-M | L1: INDINCERT | M1: dfi1
A2: 44927 | B2: 4.33 | C2: 13.65 | D2: 5.08 | E2: 226 | F2: 557.02 | G2: 102 | H2: 18.7 | I2: 5.71 | J2: 6.4883 | K2: 0.21 | L2: 113.3 | M2: =C2-B2 -> 9.32
A3: 44958 | B3: 4.57 | C3: 13.65 | D3: 5.17 | E3: 228 | F3: 548.53 | G3: 101 | H3: 25 | I3: 5.77 | J3: 6.5266 | K3: -0.06 | L3: 111.7 | M3: =C3-B3 -> 9.08
A4: 44986 | B4: 4.65 | C4: 13.65 | D4: 5.06 | E4: 225 | F4: 550.63 | G4: 101.7 | H4: 17 | I4: 5.55 | J4: 6.3906 | K4: 0.05 | L4: 116.7 | M4: =C4-B4 -> 9
A5: 45017 | B5: 4.83 | C5: 13.65 | D5: 4.98 | E5: 220 | F5: 547.45 | G5: 102 | H5: 17 | I5: 5.28 | J5: 6.2677 | K5: -0.95 | L5: 112.6 | M5: =C5-B5 -> 8.82
A6: 45047 | B6: 5.06 | C6: 13.65 | D6: 4.98 | E6: 206 | F6: 541.45 | G6: 104.2 | H6: 16.9 | I6: 4.69 | J6: 5.9789 | K6: -1.84 | L6: 111.8 | M6: =C6-B6 -> 8.59
A7: 45078 | B7: 5.08 | C7: 13.65 | D7: 4.83 | E7: 177 | F7: 547.83 | G7: 103 | H7: 16 | I7: 3.99 | J7: 5.5888 | K7: -1.93 | L7: 107.6 | M7: =C7-B7 -> 8.57
A8: 45108 | B8: 5.12 | C8: 13.65 | D8: 4.71 | E8: 162 | F8: 563.85 | G8: 102 | H8: 14.8 | I8: 4.09 | J8: 5.4029 | K8: -0.72 | L8: 103.5 | M8: =C8-B8 -> 8.53
A9: 45139 | B9: 5.33 | C9: 13.19 | D9: 4.89 | E9: 166 | F9: 552.84 | G9: 105 | H9: 13.8 | I9: 4.22 | J9: 5.1697 | K9: -0.14 | L9: 108.5 | M9: =C9-B9 -> 7.86
A10: 45170 | B10: 5.33 | C10: 12.97 | D10: 5.05 | E10: 186 | F10: 548.56 | G10: 106.6 | H10: 19 | I10: 4.11 | J10: 4.9554 | K10: 0.37 | L10: 106.8 | M10: =C10-B10 -> 7.64
A11: 45200 | B11: 5.33 | C11: 12.65 | D11: 5 | E11: 183 | F11: 539.51 | G11: 105.8 | H11: 14.7 | I11: 3.92 | J11: 4.8827 | K11: 0.5 | L11: 110.9 | M11: =C11-B11 -> 7.32
A12: 45231 | B12: 5.33 | C12: 12.17 | D12: 4.9 | E12: 146 | F12: 529.9 | G12: 104 | H12: 12.3 | I12: 3.92 | J12: 4.6913 | K12: 0.59 | L12: 110.4 | M12: =C12-B12 -> 6.84
A13: 45261 | B13: 5.33 | C13: 11.87 | D13: 4.85 | E13: 131 | F13: 510.32 | G13: 102.4 | H13: 12.7 | I13: 3.81 | J13: 4.5577 | K13: 0.74 | L13: 107 | M13: =C13-B13 -> 6.54
... A30: 45778 | B30: 4.33 | C30: 14.55 | D30: 5.72 | E30: 160 | F30: 555.02 | G30: 99 | H30: 18.57 | I30: 4.86 | J30: 3.1591 | K30: -0.49 | L30: 112.8 | M30: =C30-B30 -> 10.22
A31: 45809 | B31: 4.33 | C31: 14.74 | D31: 5.51 | E31: 156 | F31: 561 | G31: 98.49 | H31: 20.21 | I31: 4.88 | J31: 3.1591 | K31: -1.67 | L31: 112 | M31: =C31-B31 -> 10.41 | O31: 1
A32: 45839 | B32: 4.33 | C32: =C31*O32 -> 15.1822 | D32: =EXP(LN(D31)+Modelo!$C$5*(LN(F32)-LN(F31))+Modelo!$C$6*(LN(H32)-LN(H31))+Modelo!$C$7*(LN(E32)-LN(E31))+Modelo!$C$8*(LN(G32)-LN(G31))+Modelo!$C$9*(LN(L32)-LN(L31))+Modelo!$C$10*(LN(C32)-LN(C31))+Modelo!$C$11*(LN(B32)-LN(B31))+Modelo!$C$11*(M32-M31)+ Modelo!$C$13) -> 5.5149874 | E32: 150 | F32: 550 | G32: 97 | H32: 19 | L32: 112 | M32: =C32-B32 -> 10.8522 | O32: 1.03 | P32: 0.97
A33: 45870 | B33: 4.33 | C33: =C32*O33 -> 15.637666 | D33: =EXP(LN(D32)+Modelo!$C$5*(LN(F33)-LN(F32))+Modelo!$C$6*(LN(H33)-LN(H32))+Modelo!$C$7*(LN(E33)-LN(E32))+Modelo!$C$8*(LN(G33)-LN(G32))+Modelo!$C$9*(LN(L33)-LN(L32))+Modelo!$C$10*(LN(C33)-LN(C32))+Modelo!$C$11*(LN(B33)-LN(B32))+Modelo!$C$11*(M33-M32)+ Modelo!$C$13) -> 5.5450505 | E33: 150 | F33: 550 | G33: 97 | H33: 19 | L33: 112 | M33: =C33-B33 -> 11.307666 | O33: 1.03 | P33: 0.97
A34: 45901 | B34: 4.33 | C34: =C33*O34 -> 16.106796 | D34: =EXP(LN(D33)+Modelo!$C$5*(LN(F34)-LN(F33))+Modelo!$C$6*(LN(H34)-LN(H33))+Modelo!$C$7*(LN(E34)-LN(E33))+Modelo!$C$8*(LN(G34)-LN(G33))+Modelo!$C$9*(LN(L34)-LN(L33))+Modelo!$C$10*(LN(C34)-LN(C33))+Modelo!$C$11*(LN(B34)-LN(B33))+Modelo!$C$11*(M34-M33)+ Modelo!$C$13) -> 5.5739005 | E34: 150 | F34: 550 | G34: 97 | H34: 19 | L34: 112 | M34: =C34-B34 -> 11.776796 | O34: 1.03 | P34: 0.97
A35: 45931 | B35: 4.33 | C35: =C34*O35 -> 16.59 | D35: =EXP(LN(D34)+Modelo!$C$5*(LN(F35)-LN(F34))+Modelo!$C$6*(LN(H35)-LN(H34))+Modelo!$C$7*(LN(E35)-LN(E34))+Modelo!$C$8*(LN(G35)-LN(G34))+Modelo!$C$9*(LN(L35)-LN(L34))+Modelo!$C$10*(LN(C35)-LN(C34))+Modelo!$C$11*(LN(B35)-LN(B34))+Modelo!$C$11*(M35-M34)+ Modelo!$C$13) -> 5.6014755 | E35: 150 | F35: 550 | G35: 97 | H35: 19 | L35: 112 | M35: =C35-B35 -> 12.26 | O35: 1.03 | P35: 0.97
A36: 45962 | B36: 4.33 | C36: =C35*O36 -> 17.0877 | D36: =EXP(LN(D35)+Modelo!$C$5*(LN(F36)-LN(F35))+Modelo!$C$6*(LN(H36)-LN(H35))+Modelo!$C$7*(LN(E36)-LN(E35))+Modelo!$C$8*(LN(G36)-LN(G35))+Modelo!$C$9*(LN(L36)-LN(L35))+Modelo!$C$10*(LN(C36)-LN(C35))+Modelo!$C$11*(LN(B36)-LN(B35))+Modelo!$C$11*(M36-M35)+ Modelo!$C$13) -> 5.6277121 | E36: 150 | F36: 550 | G36: 97 | H36: 19 | L36: 112 | M36: =C36-B36 -> 12.7577 | O36: 1.03 | P36: 0.97
A37: 45992 | B37: 4.33 | C37: =C36*O37 -> 17.600331 | D37: =EXP(LN(D36)+Modelo!$C$5*(LN(F37)-LN(F36))+Modelo!$C$6*(LN(H37)-LN(H36))+Modelo!$C$7*(LN(E37)-LN(E36))+Modelo!$C$8*(LN(G37)-LN(G36))+Modelo!$C$9*(LN(L37)-LN(L36))+Modelo!$C$10*(LN(C37)-LN(C36))+Modelo!$C$11*(LN(B37)-LN(B36))+Modelo!$C$11*(M37-M36)+ Modelo!$C$13) -> 5.6525457 | E37: 150 | F37: 550 | G37: 97 | H37: 19 | L37: 112 | M37: =C37-B37 -> 13.270331 | O37: 1.03 | P37: 0.97
A38: 46023 | B38: 4.33 | C38: =C37*O38 -> 18.128341 | D38: =EXP(LN(D37)+Modelo!$C$5*(LN(F38)-LN(F37))+Modelo!$C$6*(LN(H38)-LN(H37))+Modelo!$C$7*(LN(E38)-LN(E37))+Modelo!$C$8*(LN(G38)-LN(G37))+Modelo!$C$9*(LN(L38)-LN(L37))+Modelo!$C$10*(LN(C38)-LN(C37))+Modelo!$C$11*(LN(B38)-LN(B37))+Modelo!$C$11*(M38-M37)+ Modelo!$C$13) -> 5.6759109 | E38: 150 | F38: 550 | G38: 97 | H38: 19 | L38: 112 | M38: =C38-B38 -> 13.798341 | O38: 1.03 | P38: 0.97
A39: 46054 | B39: 4.33 | C39: =C38*O39 -> 18.672191 | D39: =EXP(LN(D38)+Modelo!$C$5*(LN(F39)-LN(F38))+Modelo!$C$6*(LN(H39)-LN(H38))+Modelo!$C$7*(LN(E39)-LN(E38))+Modelo!$C$8*(LN(G39)-LN(G38))+Modelo!$C$9*(LN(L39)-LN(L38))+Modelo!$C$10*(LN(C39)-LN(C38))+Modelo!$C$11*(LN(B39)-LN(B38))+Modelo!$C$11*(M39-M38)+ Modelo!$C$13) -> 5.697741 | E39: 150 | F39: 550 | G39: 97 | H39: 19 | L39: 112 | M39: =C39-B39 -> 14.342191 | O39: 1.03 | P39: 0.97
A40: 46082 | B40: 4.33 | C40: =C39*O40 -> 19.232357 | D40: =EXP(LN(D39)+Modelo!$C$5*(LN(F40)-LN(F39))+Modelo!$C$6*(LN(H40)-LN(H39))+Modelo!$C$7*(LN(E40)-LN(E39))+Modelo!$C$8*(LN(G40)-LN(G39))+Modelo!$C$9*(LN(L40)-LN(L39))+Modelo!$C$10*(LN(C40)-LN(C39))+Modelo!$C$11*(LN(B40)-LN(B39))+Modelo!$C$11*(M40-M39)+ Modelo!$C$13) -> 5.7179685 | E40: 150 | F40: 550 | G40: 97 | H40: 19 | L40: 112 | M40: =C40-B40 -> 14.902357 | O40: 1.03 | P40: 0.97
A41: 46113 | B41: 4.33 | C41: =C40*O41 -> 19.809327 | D41: =EXP(LN(D40)+Modelo!$C$5*(LN(F41)-LN(F40))+Modelo!$C$6*(LN(H41)-LN(H40))+Modelo!$C$7*(LN(E41)-LN(E40))+Modelo!$C$8*(LN(G41)-LN(G40))+Modelo!$C$9*(LN(L41)-LN(L40))+Modelo!$C$10*(LN(C41)-LN(C40))+Modelo!$C$11*(LN(B41)-LN(B40))+Modelo!$C$11*(M41-M40)+ Modelo!$C$13) -> 5.736525 | E41: 150 | F41: 550 | G41: 97 | H41: 19 | L41: 112 | M41: =C41-B41 -> 15.479327 | O41: 1.03 | P41: 0.97
A42: 46143 | B42: 4.33 | C42: =C41*O42 -> 20.403607 | D42: =EXP(LN(D41)+Modelo!$C$5*(LN(F42)-LN(F41))+Modelo!$C$6*(LN(H42)-LN(H41))+Modelo!$C$7*(LN(E42)-LN(E41))+Modelo!$C$8*(LN(G42)-LN(G41))+Modelo!$C$9*(LN(L42)-LN(L41))+Modelo!$C$10*(LN(C42)-LN(C41))+Modelo!$C$11*(LN(B42)-LN(B41))+Modelo!$C$11*(M42-M41)+ Modelo!$C$13) -> 5.7533413 | E42: 150 | F42: 550 | G42: 97 | H42: 19 | L42: 112 | M42: =C42-B42 -> 16.073607 | O42: 1.03 | P42: 0.97
A43: 46174 | B43: 4.33 | C43: =C42*O43 -> 21.015715 | D43: =EXP(LN(D42)+Modelo!$C$5*(LN(F43)-LN(F42))+Modelo!$C$6*(LN(H43)-LN(H42))+Modelo!$C$7*(LN(E43)-LN(E42))+Modelo!$C$8*(LN(G43)-LN(G42))+Modelo!$C$9*(LN(L43)-LN(L42))+Modelo!$C$10*(LN(C43)-LN(C42))+Modelo!$C$11*(LN(B43)-LN(B42))+Modelo!$C$11*(M43-M42)+ Modelo!$C$13) -> 5.7683476 | E43: 150 | F43: 550 | G43: 97 | H43: 19 | L43: 112 | M43: =C43-B43 -> 16.685715 | O43: 1.03 | P43: 0.97
... A49: 46357 | B49: 4.33 | C49: =C48*O49 -> 25.093863 | D49: =EXP(LN(D48)+Modelo!$C$5*(LN(F49)-LN(F48))+Modelo!$C$6*(LN(H49)-LN(H48))+Modelo!$C$7*(LN(E49)-LN(E48))+Modelo!$C$8*(LN(G49)-LN(G48))+Modelo!$C$9*(LN(L49)-LN(L48))+Modelo!$C$10*(LN(C49)-LN(C48))+Modelo!$C$11*(LN(B49)-LN(B48))+Modelo!$C$11*(M49-M48)+ Modelo!$C$13) -> 5.8164215 | E49: 150 | F49: 550 | G49: 97 | H49: 19 | L49: 112 | M49: =C49-B49 -> 20.763863 | O49: 1.03 | P49: 0.97
O50: 1.03 | P50: 0.97
A51: 45809 | B51: 4.33 | C51: 14.74 | D51: 5.51 | E51: 156 | F51: 561 | G51: 98.49 | H51: 20.21 | I51: 4.88 | J51: 3.1591 | K51: -1.67 | L51: 112 | M51: =C51-B51 -> 10.41
A52: 45839 | B52: 4.33 | C52: =C51*P32 -> 14.2978 | D52: =EXP(LN(D51)+Modelo!$C$5*(LN(F52)-LN(F51))+Modelo!$C$6*(LN(H52)-LN(H51))+Modelo!$C$7*(LN(E52)-LN(E51))+Modelo!$C$8*(LN(G52)-LN(G51))+Modelo!$C$9*(LN(L52)-LN(L51))+Modelo!$C$10*(LN(C52)-LN(C51))+Modelo!$C$11*(LN(B52)-LN(B51))+Modelo!$C$11*(M52-M51)+ Modelo!$C$13) -> 5.6281909 | E52: 150 | F52: 550 | G52: 97 | H52: 19 | L52: 112 | M52: =C52-B52 -> 9.9678
A53: 45870 | B53: 4.33 | C53: =C52*P33 -> 13.868866 | D53: =EXP(LN(D52)+Modelo!$C$5*(LN(F53)-LN(F52))+Modelo!$C$6*(LN(H53)-LN(H52))+Modelo!$C$7*(LN(E53)-LN(E52))+Modelo!$C$8*(LN(G53)-LN(G52))+Modelo!$C$9*(LN(L53)-LN(L52))+Modelo!$C$10*(LN(C53)-LN(C52))+Modelo!$C$11*(LN(B53)-LN(B52))+Modelo!$C$11*(M53-M52)+ Modelo!$C$13) -> 5.775028 | E53: 150 | F53: 550 | G53: 97 | H53: 19 | L53: 112 | M53: =C53-B53 -> 9.538866
A54: 45901 | B54: 4.33 | C54: =C53*P34 -> 13.4528 | D54: =EXP(LN(D53)+Modelo!$C$5*(LN(F54)-LN(F53))+Modelo!$C$6*(LN(H54)-LN(H53))+Modelo!$C$7*(LN(E54)-LN(E53))+Modelo!$C$8*(LN(G54)-LN(G53))+Modelo!$C$9*(LN(L54)-LN(L53))+Modelo!$C$10*(LN(C54)-LN(C53))+Modelo!$C$11*(LN(B54)-LN(B53))+Modelo!$C$11*(M54-M53)+ Modelo!$C$13) -> 5.9243179 | E54: 150 | F54: 550 | G54: 97 | H54: 19 | L54: 112 | M54: =C54-B54 -> 9.1228
A55: 45931 | B55: 4.33 | C55: =C54*P35 -> 13.049216 | D55: =EXP(LN(D54)+Modelo!$C$5*(LN(F55)-LN(F54))+Modelo!$C$6*(LN(H55)-LN(H54))+Modelo!$C$7*(LN(E55)-LN(E54))+Modelo!$C$8*(LN(G55)-LN(G54))+Modelo!$C$9*(LN(L55)-LN(L54))+Modelo!$C$10*(LN(C55)-LN(C54))+Modelo!$C$11*(LN(B55)-LN(B54))+Modelo!$C$11*(M55-M54)+ Modelo!$C$13) -> 6.0760959 | E55: 150 | F55: 550 | G55: 97 | H55: 19 | L55: 112 | M55: =C55-B55 -> 8.719216
A56: 45962 | B56: 4.33 | C56: =C55*P36 -> 12.65774 | D56: =EXP(LN(D55)+Modelo!$C$5*(LN(F56)-LN(F55))+Modelo!$C$6*(LN(H56)-LN(H55))+Modelo!$C$7*(LN(E56)-LN(E55))+Modelo!$C$8*(LN(G56)-LN(G55))+Modelo!$C$9*(LN(L56)-LN(L55))+Modelo!$C$10*(LN(C56)-LN(C55))+Modelo!$C$11*(LN(B56)-LN(B55))+Modelo!$C$11*(M56-M55)+ Modelo!$C$13) -> 6.2303988 | E56: 150 | F56: 550 | G56: 97 | H56: 19 | L56: 112 | M56: =C56-B56 -> 8.3277395
A57: 45992 | B57: 4.33 | C57: =C56*P37 -> 12.278007 | D57: =EXP(LN(D56)+Modelo!$C$5*(LN(F57)-LN(F56))+Modelo!$C$6*(LN(H57)-LN(H56))+Modelo!$C$7*(LN(E57)-LN(E56))+Modelo!$C$8*(LN(G57)-LN(G56))+Modelo!$C$9*(LN(L57)-LN(L56))+Modelo!$C$10*(LN(C57)-LN(C56))+Modelo!$C$11*(LN(B57)-LN(B56))+Modelo!$C$11*(M57-M56)+ Modelo!$C$13) -> 6.3872641 | E57: 150 | F57: 550 | G57: 97 | H57: 19 | L57: 112 | M57: =C57-B57 -> 7.9480074
A58: 46023 | B58: 4.33 | C58: =C57*P38 -> 11.909667 | D58: =EXP(LN(D57)+Modelo!$C$5*(LN(F58)-LN(F57))+Modelo!$C$6*(LN(H58)-LN(H57))+Modelo!$C$7*(LN(E58)-LN(E57))+Modelo!$C$8*(LN(G58)-LN(G57))+Modelo!$C$9*(LN(L58)-LN(L57))+Modelo!$C$10*(LN(C58)-LN(C57))+Modelo!$C$11*(LN(B58)-LN(B57))+Modelo!$C$11*(M58-M57)+ Modelo!$C$13) -> 6.5467305 | E58: 150 | F58: 550 | G58: 97 | H58: 19 | L58: 112 | M58: =C58-B58 -> 7.5796671
A59: 46054 | B59: 4.33 | C59: =C58*P39 -> 11.552377 | D59: =EXP(LN(D58)+Modelo!$C$5*(LN(F59)-LN(F58))+Modelo!$C$6*(LN(H59)-LN(H58))+Modelo!$C$7*(LN(E59)-LN(E58))+Modelo!$C$8*(LN(G59)-LN(G58))+Modelo!$C$9*(LN(L59)-LN(L58))+Modelo!$C$10*(LN(C59)-LN(C58))+Modelo!$C$11*(LN(B59)-LN(B58))+Modelo!$C$11*(M59-M58)+ Modelo!$C$13) -> 6.7088381 | E59: 150 | F59: 550 | G59: 97 | H59: 19 | L59: 112 | M59: =C59-B59 -> 7.2223771
A60: 46082 | B60: 4.33 | C60: =C59*P40 -> 11.205806 | D60: =EXP(LN(D59)+Modelo!$C$5*(LN(F60)-LN(F59))+Modelo!$C$6*(LN(H60)-LN(H59))+Modelo!$C$7*(LN(E60)-LN(E59))+Modelo!$C$8*(LN(G60)-LN(G59))+Modelo!$C$9*(LN(L60)-LN(L59))+Modelo!$C$10*(LN(C60)-LN(C59))+Modelo!$C$11*(LN(B60)-LN(B59))+Modelo!$C$11*(M60-M59)+ Modelo!$C$13) -> 6.8736279 | E60: 150 | F60: 550 | G60: 97 | H60: 19 | L60: 112 | M60: =C60-B60 -> 6.8758058
A61: 46113 | B61: 4.33 | C61: =C60*P41 -> 10.869632 | D61: =EXP(LN(D60)+Modelo!$C$5*(LN(F61)-LN(F60))+Modelo!$C$6*(LN(H61)-LN(H60))+Modelo!$C$7*(LN(E61)-LN(E60))+Modelo!$C$8*(LN(G61)-LN(G60))+Modelo!$C$9*(LN(L61)-LN(L60))+Modelo!$C$10*(LN(C61)-LN(C60))+Modelo!$C$11*(LN(B61)-LN(B60))+Modelo!$C$11*(M61-M60)+ Modelo!$C$13) -> 7.0411419 | E61: 150 | F61: 550 | G61: 97 | H61: 19 | L61: 112 | M61: =C61-B61 -> 6.5396316
...

Sheet Modelo
B4: Coeficientes
B5: d(log(crb)) | C5: -0.269676
B6: d(log(vix)) | C6: 0.017505
B7: d(log(cds)) | C7: 0.129167
B8: d(log(dxy)) | C8: 0.260098
B9: d(log(1 + fin)) | C9: -0.007
B10: d(log(selic)) | C10: -0.072183
B11: d(log(fed)) | C11: -0.018076
B12: dif1 | C12: -0.1297
B13: C | C13: 0.015803
